Workbook

Sheet HORARIOS_ENE_2026
A1: REGION | B1: ADMINISTRADOR | C1: UNIDAD DE NEGOCIO | D1: 1 | F1: 2 | H1: 3 | J1: 4 | L1: 5 | N1: 6 | P1: 7 | R1: 8 | T1: 9 | V1: 10 | X1: 11 | Z1: 12 | AB1: 13 | AD1: 14 | AF1: 15 | AH1: 16 | AJ1: 17 | AL1: 18 | AN1: 19 | AP1: 20 | AR1: 21 | AT1: 22 | AV1: 23 | AX1: 24 | AZ1: 25 | BB1: 26 | BD1: 27 | BF1: 28 | BH1: 29 | BJ1: 30 | BL1: 31
D2: M | E2: V | F2: M | G2: V | H2: M | I2: V | J2: M | K2: V | L2: M | M2: V | N2: M | O2: V | P2: M | Q2: V | R2: M | S2: V | T2: M | U2: V | V2: M | W2: V | X2: M | Y2: V | Z2: M | AA2: V | AB2: M | AC2: V | AD2: M | AE2: V | AF2: M | AG2: V | AH2: M | AI2: V | AJ2: M | AK2: V | AL2: M | AM2: V | AN2: M | AO2: V | AP2: M | AQ2: V | AR2: M | AS2: V | AT2: M | AU2: V | AV2: M | AW2: V | AX2: M | AY2: V | AZ2: M | BA2: V | BB2: M | BC2: V | BD2: M | BE2: V | BF2: M | BG2: V | BH2: M | BI2: V | BJ2: M | BK2: V | BL2: M | BM2: V
A3: R1 | B3: ALFREDO OLVERA | C3: AZCAPOPARK | Z3: 0.35069444 | AA3: 0.16111111 | AB3: 0.36666667 | AC3: 0.16458333 | AD3: 0.35347222 | AE3: 0.16388889 | AF3: 0.35833333 | AH3: 0.34652778 | AI3: 0.16458333 | AN3: 0.35486111 | AO3: 0.16944444 | AP3: 0.35625 | AQ3: 0.16597222 | AR3: 0.35138889 | AS3: 0.16597222 | AT3: 0.35555556 | AU3: 0.16041667 | AV3: 0.35763889 | AX3: 0.35972222 | AY3: 0.50069444 | BB3: 0.35486111 | BN3: =A3&"|"&B3&"|"&C3 -> R1|ALFREDO OLVERA|AZCAPOPARK
A4: R1 | B4: ALFREDO OLVERA | C4: VALLEJO PARK | F4: 0.37986111 | G4: 0.68819444 | L4: 0.36041667 | M4: 0.66388889 | N4: 0.35972222 | R4: 0.40069444 | T4: 0.35833333 | U4: 0.67569444 | V4: 0.37777778 | W4: 0.57361111 | AU4: 0.16041667 | AW4: 0.17777778 | BN4: =A4&"|"&B4&"|"&C4 -> R1|ALFREDO OLVERA|VALLEJO PARK
A5: R1 | B5: MARTIN BAUME | C5: GB | Z5: 0.34652778 | AA5: 0.14930556 | AB5: 0.34930556 | AC5: 0.17222222 | AD5: 0.35625 | AE5: 0.20763889 | AF5: 0.33819444 | AH5: 0.3375 | AI5: 0.17013889 | AN5: 0.35 | AO5: 0.17430556 | AP5: 0.35277778 | AQ5: 0.16111111 | AR5: 0.35763889 | AS5: 0.14097222 | AU5: 0.16666667 | AV5: 0.35416667 | AW5: 0.16458333 | AX5: 0.34583333 | BB5: 0.37430556 | BN5: =A5&"|"&B5&"|"&C5 -> R1|MARTIN BAUME|GB
A6: R1 | B6: MARTIN BAUME | C6: CEYLAN | F6: 0.35902778 | G6: 0.66597222 | L6: 0.3625 | M6: 0.67430556 | N6: 0.34722222 | O6: 0.64375 | R6: 0.36666667 | S6: 0.65625 | T6: 0.37013889 | U6: 0.66388889 | AT6: 0.36111111 | BN6: =A6&"|"&B6&"|"&C6 -> R1|MARTIN BAUME|CEYLAN
A7: R1 | B7: MARTIN BAUME | C7: 100 METROS | BN7: =A7&"|"&B7&"|"&C7 -> R1|MARTIN BAUME|100 METROS
A8: R1 | B8: MARTIN BAUME | C8: PINO | BN8: =A8&"|"&B8&"|"&C8 -> R1|MARTIN BAUME|PINO
A9: R1 | B9: MARTIN BAUME | C9: VALLEJO 1746 | BN9: =A9&"|"&B9&"|"&C9 -> R1|MARTIN BAUME|VALLEJO 1746
A10: R1 | B10: JAIR ABRAHAM GONZALEZ | C10: TLANE PARK III | Z10: 0.36319444 | AA10: 0.16597222 | AB10: 0.35138889 | AC10: 0.16180556 | AD10: 0.35416667 | AE10: 0.12638889 | AF10: 0.35972222 | AH10: 0.35416667 | AI10: 0.13263889 | AO10: 0.15347222 | AP10: 0.3625 | AR10: 0.35208333 | AS10: 0.16041667 | AT10: 0.35555556 | AU10: 0.18472222 | BB10: 0.35833333 | BN10: =A10&"|"&B10&"|"&C10 -> R1|JAIR ABRAHAM GONZALEZ|TLANE PARK III
A11: R1 | B11: JAIR ABRAHAM GONZALEZ | C11: VIA MORELOS | AN11: 0.35972222 | AV11: 0.36041667 | BN11: =A11&"|"&B11&"|"&C11 -> R1|JAIR ABRAHAM GONZALEZ|VIA MORELOS
A12: R1 | B12: JAIR ABRAHAM GONZALEZ | C12: TLANE PARK V | BN12: =A12&"|"&B12&"|"&C12 -> R1|JAIR ABRAHAM GONZALEZ|TLANE PARK V
A13: R1 | B13: JAIR ABRAHAM GONZALEZ | C13: VALLEJO 2000 | BN13: =A13&"|"&B13&"|"&C13 -> R1|JAIR ABRAHAM GONZALEZ|VALLEJO 2000
A14: R1 | B14: JAIR ABRAHAM GONZALEZ | C14: LA PRESA | BN14: =A14&"|"&B14&"|"&C14 -> R1|JAIR ABRAHAM GONZALEZ|LA PRESA
A15: R1 | B15: JAIR ABRAHAM GONZALEZ | C15: CHIQUIHUITE (WALMART) | BN15: =A15&"|"&B15&"|"&C15 -> R1|JAIR ABRAHAM GONZALEZ|CHIQUIHUITE (WALMART)
A16: R1 | B16: GEOVANI PEÑA | C16: LOS REYES | Z16: 0.33680556 | AA16: 0.17013889 | AB16: 0.35277778 | AD16: 0.34791667 | AE16: 0.17361111 | AH16: 0.32847222 | AI16: 0.18194444 | AJ16: 0.36736111 | AN16: 0.35208333 | AO16: 0.16944444 | AP16: 0.35902778 | AQ16: 0.17291667 | AR16: 0.33611111 | AS16: 0.18680556 | AT16: 0.35416667 | AU16: 0.17777778 | AV16: 0.33888889 | AW16: 0.17986111 | BB16: 0.32708333 | BN16: =A16&"|"&B16&"|"&C16 -> R1|GEOVANI PEÑA|LOS REYES
A17: R1 | B17: GEOVANI PEÑA | C17: IXTAPALUCA | H17: 0.35416667 | L17: 0.31597222 | M17: 0.66319444 | N17: 0.32569444 | O17: 0.66319444 | P17: 0.33055556 | Q17: 0.70902778 | R17: 0.32847222 | S17: 0.66666667 | T17: 0.33472222 | U17: 0.68194444 | BN17: =A17&"|"&B17&"|"&C17 -> R1|GEOVANI PEÑA|IXTAPALUCA
A18: R1 | B18: GEOVANI PEÑA | C18: IZTAPALAPA | BN18: =A18&"|"&B18&"|"&C18 -> R1|GEOVANI PEÑA|IZTAPALAPA
A19: R2 | B19: OMAR SANCHEZ | C19: TULTI PARK I | Z19: 0.37777778 | AA19: 0.12708333 | AB19: 0.38125 | AC19: 0.12569444 | AD19: 0.38402778 | AE19: 0.13888889 | AF19: 0.37916667 | AG19: 0.13125 | AH19: 0.38680556 | AI19: 0.12638889 | AJ19: 0.38333333 | AN19: 0.38125 | AO19: 0.13194444 | AP19: 0.37986111 | AQ19: 0.13055556 | AR19: 0.38472222 | AT19: 0.45138889 | AU19: 0.12222222 | AV19: 0.38472222 | AW19: 0.16180556 | BB19: 0.37847222 | BN19: =A19&"|"&B19&"|"&C19 -> R2|OMAR SANCHEZ|TULTI PARK I
A20: R2 | B20: ARTURO ESPINOSA | C20: JAMES WATT | F20: 0.35625 | G20: 0.60416667 | H20: 0.37083333 | L20: 0.35555556 | M20: 0.63263889 | N20: 0.34861111 | O20: 0.63472222 | P20: 0.34444444 | Q20: 0.63888889 | R20: 0.34097222 | S20: 0.64097222 | T20: 0.34444444 | U20: 0.60902778 | V20: 0.35625 | Z20: 0.34791667 | AA20: 0.12430556 | AB20: 0.34861111 | AC20: 0.092361111 | AD20: 0.34375 | AE20: 0.11319444 | AF20: 0.34444444 | AG20: 0.10555556 | AH20: 0.34097222 | AI20: 0.10208333 | AN20: 0.35347222 | AO20: 0.12916667 | AP20: 0.35694444 | AQ20: 0.14236111 | AR20: 0.36666667 | AS20: 0.13819444 | AT20: 0.39444444 | AU20: 0.12986111 | AV20: 0.33958333 | AW20: 0.13055556 | AX20: 0.30555556 | BB20: 0.35416667 | BN20: =A20&"|"&B20&"|"&C20 -> R2|ARTURO ESPINOSA|JAMES WATT
A21: R2 | B21: ARTURO VALERIO | C21: LA PALMA | Z21: 0.3625 | AA21: 0.15833333 | AD21: 0.37638889 | AE21: 0.19513889 | AF21: 0.38611111 | AN21: 0.38402778 | AP21: 0.37986111 | AQ21: 0.13611111 | BN21: =A21&"|"&B21&"|"&C21 -> R2|ARTURO VALERIO|LA PALMA
A22: R2 | B22: ARTURO VALERIO | C22: LA JOYA I Y II | AC22: 0.15416667 | AH22: 0.36875 | AR22: 0.38541667 | BN22: =A22&"|"&B22&"|"&C22 -> R2|ARTURO VALERIO|LA JOYA I Y II
A23: R2 | B23: ARTURO VALERIO | C23: LA JOYA III | AG23: 0.19097222 | AO23: 0.13958333 | AT23: 0.34861111 | BN23: =A23&"|"&B23&"|"&C23 -> R2|ARTURO VALERIO|LA JOYA III
A24: R2 | B24: ARTURO VALERIO | C24: LA JOYA IV | BN24: =A24&"|"&B24&"|"&C24 -> R2|ARTURO VALERIO|LA JOYA IV
A25: R2 | B25: ARTURO VALERIO | C25: LA JOYA V | BN25: =A25&"|"&B25&"|"&C25 -> R2|ARTURO VALERIO|LA JOYA V
A26: R2 | B26: ARTURO VALERIO | C26: DIAMANTE | AU26: 0.13888889 | BB26: 0.37777778 | BN26: =A26&"|"&B26&"|"&C26 -> R2|ARTURO VALERIO|DIAMANTE
A27: R2 | B27: ARTURO VALERIO | C27: PUMA | AB27: 0.37638889 | AV27: 0.35347222 | BN27: =A27&"|"&B27&"|"&C27 -> R2|ARTURO VALERIO|PUMA
A28: R2 | B28: MONSERRAT ESQUIVEL | C28: TULTITLAN I | Z28: 0.35625 | AA28: 0.14375 | AB28: 0.38194444 | AC28: 0.14930556 | AD28: 0.40277778 | AE28: 0.15 | AF28: 0.39791667 | AG28: 0.15138889 | AH28: 0.36597222 | AI28: 0.14791667 | AN28: 0.37986111 | AO28: 0.15625 | AP28: 0.38472222 | AR28: 0.38055556 | AT28: 0.37430556 | AU28: 0.14861111 | AV28: 0.38541667 | AW28: 0.15347222 | BB28: 0.37361111 | BN28: =A28&"|"&B28&"|"&C28 -> R2|MONSERRAT ESQUIVEL|TULTITLAN I
A29: R2 | B29: RAFAEL PONCE | C29: TULTITLAN II | F29: 0.36944444 | G29: 0.65138889 | L29: 0.37291667 | M29: 0.66944444 | N29: 0.38472222 | O29: 0.64583333 | P29: 0.38888889 | Q29: 0.64652778 | R29: 0.36319444 | S29: 0.64722222 | T29: 0.37013889 | U29: 0.65486111 | Z29: 0.36666667 | AA29: 0.19444444 | AB29: 0.37708333 | AC29: 0.16597222 | AF29: 0.40347222 | AG29: 0.1375 | AN29: 0.36805556 | AP29: 0.37777778 | AR29: 0.35416667 | AT29: 0.36527778 | AV29: 0.36666667 | AW29: 0.13680556 | BB29: 0.36527778 | BN29: =A29&"|"&B29&"|"&C29 -> R2|RAFAEL PONCE|TULTITLAN II
A30: R3 | B30: CARLOS A. CARRILLO | C30: TULTI PARK II | F30: 0.38541667 | G30: 0.69583333 | H30: 0.475 | L30: 0.42986111 | M30: 0.69166667 | N30: 0.44861111 | O30: 0.67638889 | P30: 0.4 | Q30: 0.68055556 | R30: 0.37152778 | S30: 0.70625 | T30: 0.37222222 | U30: 0.61944444 | V30: 0.37986111 | Z30: 0.35972222 | AA30: 0.13958333 | AB30: 0.35694444 | AC30: 0.13611111 | AD30: 0.41736111 | AE30: 0.11666667 | AF30: 0.37708333 | AG30: 0.21041667 | AH30: 0.37152778 | AI30: 0.14166667 | AJ30: 0.42708333 | AN30: 0.3625 | AO30: 0.15 | AP30: 0.41527778 | AQ30: 0.14166667 | AR30: 0.35277778 | AS30: 0.15555556 | AT30: 0.37361111 | AU30: 0.1375 | AV30: 0.36805556 | AW30: 0.12986111 | BN30: =A30&"|"&B30&"|"&C30 -> R3|CARLOS A. CARRILLO|TULTI PARK II
A31: R3 | B31: IVAN GONZALEZ | C31: TULTI PARK III | L31: 0.34305556 | M31: 0.64930556 | R31: 0.34305556 | S31: 0.62777778 | T31: 0.34861111 | U31: 0.62638889 | Z31: 0.35763889 | AA31: 0.15486111 | AB31: 0.3625 | AC31: 0.15 | AD31: 0.37222222 | AE31: 0.13402778 | AF31: 0.36180556 | AG31: 0.14722222 | AH31: 0.36805556 | AI31: 0.14375 | AN31: 0.34722222 | AO31: 0.13125 | AP31: 0.37222222 | AQ31: 0.16875 | AR31: 0.35416667 | AS31: 0.13472222 | AT31: 0.35277778 | AU31: 0.17152778 | AV31: 0.36805556 | AW31: 0.15486111 | BB31: 0.35069444 | BN31: =A31&"|"&B31&"|"&C31 -> R3|IVAN GONZALEZ|TULTI PARK III
A32: R3 | B32: ANDREA F. MIRANDA | C32: TULTI PARK IV | F32: 0.35347222 | G32: 0.70694444 | L32: 0.37430556 | M32: 0.67777778 | N32: 0.36458333 | O32: 0.675 | P32: 0.3625 | Q32: 0.65069444 | R32: 0.35902778 | S32: 0.65555556 | T32: 0.3625 | U32: 0.65138889 | Z32: 0.37013889 | AA32: 0.15555556 | AB32: 0.35902778 | AD32: 0.37777778 | AE32: 0.15972222 | AF32: 0.37083333 | AH32: 0.36319444 | AI32: 0.15694444 | AJ32: 0.39652778 | AN32: 0.37013889 | AP32: 0.38263889 | AQ32: 0.18472222 | AR32: 0.36666667 | AS32: 0.20277778 | AT32: 0.36666667 | AU32: 0.14861111 | AV32: 0.37708333 | BB32: 0.38194444 | BN32: =A32&"|"&B32&"|"&C32 -> R3|ANDREA F. MIRANDA|TULTI PARK IV
A33: R3 | B33: ANDREA F. MIRANDA | C33: COACALCO | BN33: =A33&"|"&B33&"|"&C33 -> R3|ANDREA F. MIRANDA|COACALCO
A34: R3 | B34: MARCO A. CERVANTES | C34: MEXIQUENSE | F34: 0.35486111 | G34: 0.69097222 | L34: 0.34930556 | M34: 0.64652778 | N34: 0.34930556 | O34: 0.63611111 | P34: 0.35069444 | Q34: 0.66111111 | R34: 0.35 | T34: 0.35486111 | U34: 0.64513889 | Z34: 0.35763889 | AA34: 0.15902778 | AB34: 0.34513889 | AC34: 0.16180556 | AD34: 0.36875 | AE34: 0.15208333 | AF34: 0.35555556 | AG34: 0.13541667 | AH34: 0.36597222 | AI34: 0.12430556 | AJ34: 0.36111111 | AN34: 0.35625 | AO34: 0.15208333 | AP34: 0.3625 | AQ34: 0.13263889 | AR34: 0.3625 | AS34: 0.11458333 | AT34: 0.36319444 | AU34: 0.175 | AV34: 0.34652778 | BB34: 0.34791667 | BN34: =A34&"|"&B34&"|"&C34 -> R3|MARCO A. CERVANTES|MEXIQUENSE
A35: R3 | B35: MARCO A. CERVANTES | C35: COACALCO II | AC35: 0.16597222 | AD35: 0.36875 | AT35: 0.48194444
A36: R3 | B36: PAOLA S. ANSELMO | C36: TULTE PARK | F36: 0.35972222 | G36: 0.64722222 | L36: 0.35833333 | M36: 0.67708333 | N36: 0.35208333 | P36: 0.34861111 | Q36: 0.69236111 | R36: 0.34861111 | S36: 0.65833333 | T36: 0.34375 | U36: 0.67430556 | V36: 0.39722222 | Z36: 0.35763889 | AA36: 0.16666667 | AB36: 0.35694444 | AC36: 0.10069444 | AD36: 0.36458333 | AF36: 0.34583333 | AG36: 0.13611111 | AH36: 0.33055556 | AI36: 0.13402778 | AN36: 0.35972222 | AO36: 0.18055556 | AP36: 0.36111111 | AQ36: 0.12916667 | AR36: 0.41597222 | AT36: 0.35972222 | AU36: 0.16875 | AV36: 0.37777778 | AW36: 0.13055556 | AX36: 0.38125 | BB36: 0.35416667 | BN36: =A36&"|"&B36&"|"&C36 -> R3|PAOLA S. ANSELMO|TULTE PARK
A37: R4 | B37: JESUS BECERRA | C37: LAGO I | F37: 0.37916667 | L37: 0.35763889 | M37: 0.64583333 | N37: 0.35833333 | P37: 0.38888889 | R37: 0.375 | S37: 0.68472222 | T37: 0.38541667 | V37: 0.37986111 | AR37: 0.375 | AS37: 0.13472222 | BN37: =A37&"|"&B37&"|"&C37 -> R4|JESUS BECERRA|LAGO I
A38: R4 | B38: JESUS BECERRA | C38: LAGO II | F38: 0.40347222 | G38: 0.675 | H38: 0.40416667 | O38: 0.66597222 | Q38: 0.63263889 | U38: 0.65486111 | Z38: 0.35555556 | AA38: 0.16875 | AB38: 0.32986111 | AC38: 0.12291667 | AD38: 0.37291667 | AE38: 0.125 | AF38: 0.36041667 | AG38: 0.15833333 | AH38: 0.39097222 | AI38: 0.13819444 | AJ38: 0.35347222 | AK38: 0.53541667 | AN38: 0.37152778 | AO38: 0.17222222 | AP38: 0.36319444 | AQ38: 0.14236111 | AT38: 0.37152778 | AU38: 0.16180556 | AV38: 0.3625 | AW38: 0.12638889 | AX38: 0.38541667 | BB38: 0.3625 | BN38: =A38&"|"&B38&"|"&C38 -> R4|JESUS BECERRA|LAGO II
A39: R4 | B39: EDGAR S. MARQUEZ | C39: LAGO III | AB39: 0.36111111 | AC39: 0.15902778 | AF39: 0.35902778 | AG39: 0.14375 | AI39: 0.13402778 | AN39: 0.36319444 | AR39: 0.35486111 | AS39: 0.15763889 | AW39: 0.14791667 | BN39: =A39&"|"&B39&"|"&C39 -> R4|EDGAR S. MARQUEZ|LAGO III
A40: R4 | B40: EDGAR S. MARQUEZ | C40: FUNO CENTER | L40: 0.35555556 | M40: 0.65 | N40: 0.35347222 | O40: 0.65486111 | P40: 0.35138889 | Q40: 0.65277778 | R40: 0.35069444 | S40: 0.65625 | T40: 0.35833333 | U40: 0.65208333 | V40: 0.36666667 | Z40: 0.37638889 | AA40: 0.13611111 | AE40: 0.15694444 | AH40: 0.35347222 | AI40: 0.19166667 | AP40: 0.34861111 | AQ40: 0.15694444 | AT40: 0.36180556 | AU40: 0.16388889 | AX40: 0.35625 | BN40: =A40&"|"&B40&"|"&C40 -> R4|EDGAR S. MARQUEZ|FUNO CENTER
...

Sheet ESTADISTICAS
C1: CUMPLIMIENTO TOP 5 MARZO 2026
B3: 20 DÍAS | D3: ABRIL | E3: WHATSAPP – IMAGEN | Q3: CUMPLIMIENTO TOP 5
B4: REGIÓN | C4: ADMINISTRADOR | D4: UNIDAD DE NEGOCIO | E4: Matutino | F4: % | G4: Vespertino | H4: % | I4: TOTAL | J4: CUMPLIMINETO | R4: REGIÓN | S4: FEBRERO | T4: MARZO | U4: ABRIL | V4: MAYO
B5: R1 | C5: ALFREDO OLVERA | D5: AZCAPOPARK | E5: =' TOP ABRIL 2026'!BL3+' TOP ABRIL 2026'!BL4 -> 20 | F5: =E5/20 -> 1 | G5: =' TOP ABRIL 2026'!BM3+' TOP ABRIL 2026'!BM4 -> 20 | H5: =G5/20 -> 1 | I5: =E5+G5 -> 40 | J5: =I5/40 -> 1 | Q5: AZCAPO | R5: 1 | S5: ='FEBRERO 2026'!S4 -> 0.99305556 | T5: 0.92857143 | U5: =AVERAGE(J5:J20) -> 0.96875 | V5: 0.99305556
B6: R1 | C6: ALFREDO OLVERA | D6: VALLEJO PARK | Q6: TULTITLÁN | R6: 2 | S6: ='FEBRERO 2026'!S5 -> 0.79444444 | T6: 0.89047619 | U6: =AVERAGE(J21:J31) -> 0.95 | V6: 0.94444444
B7: R1 | C7: MARTIN BAUME | D7: GB | E7: =' TOP ABRIL 2026'!BL5+' TOP ABRIL 2026'!BL6 -> 20 | F7: =E7/20 -> 1 | G7: =' TOP ABRIL 2026'!BM5 -> 20 | H7: =G7/20 -> 1 | I7: =E7+G7 -> 40 | J7: =I7/40 -> 1 | Q7: TULTIPARK | R7: 3 | S7: ='FEBRERO 2026'!S6 -> 0.95555556 | T7: 0.92380952 | U7: =AVERAGE(J32:J38) -> 0.915 | V7: 0.95555556
B8: R1 | C8: MARTIN BAUME | D8: CEYLAN | Q8: SMO | R8: 4 | S8: ='FEBRERO 2026'!S7 -> #REF! | T8: 0.81349206 | U8: =AVERAGE(J39:J47) -> 0.8625 | V8: 0.92833333
B9: R1 | C9: MARTIN BAUME | D9: 100 METROS | Q9: TEPOTZOTLÁN | R9: 5 | S9: ='FEBRERO 2026'!S8 -> 0.98611111 | T9: 0.92857143 | U9: =AVERAGE(J48:J62) -> 0.89166667 | V9: 0.98611111
B10: R1 | C10: MARTIN BAUME | D10: PINO | Q10: QRO | R10: 6 | S10: ='FEBRERO 2026'!S9 -> 0.75694444 | T10: 0.81547619 | U10: =AVERAGE(J64:J69) -> 0.7625 | V10: 0.91694444
B11: R1 | C11: MARTIN BAUME | D11: VALLEJO 1746 | Q11: TOLUCA | R11: 7 | S11: ='FEBRERO 2026'!S10 -> 0.84722222 | T11: 0.78174603 | U11: =AVERAGE(J70:J77) -> 0.85416667 | V11: 0.91722222
B12: R1 | C12: JAIR ABRAHAM GONZALEZ | D12: TLANE PARK III | E12: =' TOP ABRIL 2026'!BL10+' TOP ABRIL 2026'!BL11 -> 20 | F12: =E12/20 -> 1 | G12: =' TOP ABRIL 2026'!BM10+' TOP ABRIL 2026'!BM11+' TOP ABRIL 2026'!BM12+' TOP ABRIL 2026'!BM15 -> 19 | H12: =G12/20 -> 0.95 | I12: =E12+G12 -> 39 | J12: =I12/40 -> 0.975 | Q12: GUADALAJARA | R12: 8 | S12: ='FEBRERO 2026'!S11 -> 0.81111111 | T12: 0.86904762 | U12: =AVERAGE(J78:J83) -> 1 | V12: 1
B13: R1 | C13: JAIR ABRAHAM GONZALEZ | D13: VIA MORELOS | Q13: MONTERREY | R13: 9 | S13: ='FEBRERO 2026'!S12 -> 0.80555556 | T13: 0.71428571 | U13: =AVERAGE(J84) -> 0.925 | V13: 0.9933
B14: R1 | C14: JAIR ABRAHAM GONZALEZ | D14: TLANE PARK V | Q14: CANCÚN | R14: 10 | S14: ='FEBRERO 2026'!S13 -> 0.77777778 | T14: 0.80357143 | U14: =AVERAGE(J93:J95) -> 0.86666667 | V14: 0.97777778
B15: R1 | C15: JAIR ABRAHAM GONZALEZ | D15: VALLEJO 2000 | Q15: BALBROS | R15: GRUPO BALBROS | S15: ='FEBRERO 2026'!S14 -> 0.309375 | T15: 0.61428571 | U15: =AVERAGE(J96:J103) -> 0.905 | V15: 0.939375
B16: R1 | C16: JAIR ABRAHAM GONZALEZ | D16: LA PRESA | Q16: T-MEX PARK | R16: T-MEX | S16: ='FEBRERO 2026'!S15 -> 1.0555556 | T16: 1 | U16: =AVERAGE(J63) -> 1 | V16: 1
B17: R1 | C17: JAIR ABRAHAM GONZALEZ | D17: CHIQUIHUITE (WALMART) | R17: GENERAL | S17: =AVERAGE(S5:S16) -> #REF! | T17: 0.84027778 | U17: =AVERAGE(U5:U16) -> 0.9084375 | V17: 0.96675347
B18: R1 | C18: GEOVANI PEÑA | D18: LOS REYES | E18: =' TOP ABRIL 2026'!BL16 -> 20 | F18: =E18/20 -> 1 | G18: =' TOP ABRIL 2026'!BM16+' TOP ABRIL 2026'!BM17+' TOP ABRIL 2026'!BM18 -> 16 | H18: =G18/20 -> 0.8 | I18: =E18+G18 -> 36 | J18: =I18/40 -> 0.9
B19: R1 | C19: GEOVANI PEÑA | D19: IXTAPALUCA
B20: R1 | C20: GEOVANI PEÑA | D20: IZTAPALAPA
B21: R2 | C21: OMAR SANCHEZ | D21: TULTI PARK I | E21: =' TOP ABRIL 2026'!BL19 -> 20 | F21: =E21/20 -> 1 | G21: =' TOP ABRIL 2026'!BM19 -> 20 | H21: =G21/20 -> 1 | I21: =E21+G21 -> 40 | J21: =I21/40 -> 1
B22: R2 | C22: ARTURO ESPINOSA | D22: JAMES WATT | E22: =' TOP ABRIL 2026'!BL20 -> 20 | F22: =E22/20 -> 1 | G22: =' TOP ABRIL 2026'!BM20 -> 20 | H22: =G22/20 -> 1 | I22: =E22+G22 -> 40 | J22: =I22/40 -> 1
B23: R2 | C23: ARTURO VALERIO | D23: LA PALMA | E23: =' TOP ABRIL 2026'!BL21+' TOP ABRIL 2026'!BL22+' TOP ABRIL 2026'!BL23+' TOP ABRIL 2026'!BL24+' TOP ABRIL 2026'!BL25+' TOP ABRIL 2026'!BL26 -> 20 | F23: =E23/20 -> 1 | G23: =' TOP ABRIL 2026'!BM21+' TOP ABRIL 2026'!BM23+' TOP ABRIL 2026'!BM24 -> 16 | H23: =G23/20 -> 0.8 | I23: =E23+G23 -> 36 | J23: =I23/40 -> 0.9
B24: R2 | C24: ARTURO VALERIO | D24: LA JOYA I Y II
B25: R2 | C25: ARTURO VALERIO | D25: LA JOYA III
B26: R2 | C26: ARTURO VALERIO | D26: LA JOYA IV
B27: R2 | C27: ARTURO VALERIO | D27: LA JOYA V
B28: R2 | C28: ARTURO VALERIO | D28: DIAMANTE
B29: R2 | C29: ARTURO VALERIO | D29: PUMA
B30: R2 | C30: MONSERRAT ESQUIVEL | D30: TULTITLAN I | E30: =' TOP ABRIL 2026'!BL28 -> 19 | F30: =E30/20 -> 0.95 | G30: =' TOP ABRIL 2026'!BM28 -> 19 | H30: =G30/20 -> 0.95 | I30: =E30+G30 -> 38 | J30: =I30/40 -> 0.95
B31: R2 | C31: RAFAEL PONCE | D31: TULTITLAN II | E31: =' TOP ABRIL 2026'!BL29 -> 19 | F31: =E31/20 -> 0.95 | G31: =' TOP ABRIL 2026'!BM29 -> 17 | H31: =G31/20 -> 0.85 | I31: =E31+G31 -> 36 | J31: =I31/40 -> 0.9
B32: R3 | C32: CARLOS A. CARRILLO | D32: TULTI PARK II | E32: =' TOP ABRIL 2026'!BL30 -> 20 | F32: =E32/20 -> 1 | G32: =' TOP ABRIL 2026'!BM30 -> 18 | H32: =G32/20 -> 0.9 | I32: =E32+G32 -> 38 | J32: =I32/40 -> 0.95
B33: R3 | C33: IVAN GONZALEZ | D33: TULTI PARK III | E33: =' TOP ABRIL 2026'!BL31 -> 20 | F33: =E33/20 -> 1 | G33: =' TOP ABRIL 2026'!BM31 -> 18 | H33: =G33/20 -> 0.9 | I33: =E33+G33 -> 38 | J33: =I33/40 -> 0.95
B34: R3 | C34: ANDREA F. MIRANDA | D34: TULTI PARK IV | E34: =' TOP ABRIL 2026'!BL32+' TOP ABRIL 2026'!BL33 -> 20 | F34: =E34/20 -> 1 | G34: =' TOP ABRIL 2026'!BM32 -> 18 | H34: =G34/20 -> 0.9 | I34: =E34+G34 -> 38 | J34: =I34/40 -> 0.95
B35: R3 | C35: ANDREA F. MIRANDA | D35: COACALCO
B36: R3 | C36: MARCO A. CERVANTES | D36: MEXIQUENSE | E36: =' TOP ABRIL 2026'!BL34+' TOP ABRIL 2026'!BL35 -> 20 | F36: =E36/20 -> 1 | G36: =' TOP ABRIL 2026'!BM34+' TOP ABRIL 2026'!BM35 -> 11 | H36: =G36/20 -> 0.55 | I36: =E36+G36 -> 31 | J36: =I36/40 -> 0.775
B37: R3 | C37: MARCO A. CERVANTES | D37: COACALCO II
B38: R3 | C38: PAOLA S. ANSELMO | D38: TULTE PARK | E38: =' TOP ABRIL 2026'!BL36 -> 20 | F38: =E38/20 -> 1 | G38: =' TOP ABRIL 2026'!BM36 -> 18 | H38: =G38/20 -> 0.9 | I38: =E38+G38 -> 38 | J38: =I38/40 -> 0.95
B39: R4 | C39: JESUS BECERRA | D39: LAGO I | E39: =' TOP ABRIL 2026'!BL38 -> 20 | F39: =E39/20 -> 1 | G39: =' TOP ABRIL 2026'!BM38 -> 16 | H39: =G39/20 -> 0.8 | I39: =E39+G39 -> 36 | J39: =I39/40 -> 0.9
B40: R4 | C40: JESUS BECERRA | D40: LAGO II
B41: R4 | C41: EDGAR S. MARQUEZ | D41: LAGO III | E41: =' TOP ABRIL 2026'!BL39+' TOP ABRIL 2026'!BL40 -> 20 | F41: =E41/20 -> 1 | G41: =' TOP ABRIL 2026'!BM39+' TOP ABRIL 2026'!BM40 -> 18 | H41: =G41/20 -> 0.9 | I41: =E41+G41 -> 38 | J41: =I41/40 -> 0.95
...

Sheet HORARIOS_DIC_2025
A1: REGION | B1: ADMINISTRADOR | C1: UNIDAD DE NEGOCIO | D1: 1 | F1: 2 | H1: 3 | J1: 4 | L1: 5 | N1: 6 | P1: 7 | R1: 8 | T1: 9 | V1: 10 | X1: 11 | Z1: 12 | AB1: 13 | AD1: 14 | AF1: 15 | AH1: 16 | AJ1: 17 | AL1: 18 | AN1: 19 | AP1: 20 | AR1: 21 | AT1: 22 | AV1: 23 | AX1: 24 | AZ1: 25 | BB1: 26 | BD1: 27 | BF1: 28 | BH1: 29 | BJ1: 30 | BL1: 31
D2: M | E2: V | F2: M | G2: V | H2: M | I2: V | J2: M | K2: V | L2: M | M2: V | N2: M | O2: V | P2: M | Q2: V | R2: M | S2: V | T2: M | U2: V | V2: M | W2: V | X2: M | Y2: V | Z2: M | AA2: V | AB2: M | AC2: V | AD2: M | AE2: V | AF2: M | AG2: V | AH2: M | AI2: V | AJ2: M | AK2: V | AL2: M | AM2: V | AN2: M | AO2: V | AP2: M | AQ2: V | AR2: M | AS2: V | AT2: M | AU2: V | AV2: M | AW2: V | AX2: M | AY2: V | AZ2: M | BA2: V | BB2: M | BC2: V | BD2: M | BE2: V | BF2: M | BG2: V | BH2: M | BI2: V | BJ2: M | BK2: V | BL2: M | BM2: V
D3: INICIO TOP MATUTINO | E3: INICIO TOP VESPERTINO | F3: INICIO TOP MATUTINO | G3: INICIO TOP VESPERTINO | H3: INICIO TOP MATUTINO | I3: INICIO TOP VESPERTINO | J3: INICIO TOP MATUTINO | K3: INICIO TOP VESPERTINO | L3: INICIO TOP MATUTINO | M3: INICIO TOP VESPERTINO | N3: INICIO TOP MATUTINO | O3: INICIO TOP VESPERTINO | P3: INICIO TOP MATUTINO | Q3: INICIO TOP VESPERTINO | R3: INICIO TOP MATUTINO | S3: INICIO TOP VESPERTINO | T3: INICIO TOP MATUTINO | U3: INICIO TOP VESPERTINO | V3: INICIO TOP MATUTINO | W3: INICIO TOP VESPERTINO | X3: INICIO TOP MATUTINO | Y3: INICIO TOP VESPERTINO | Z3: INICIO TOP MATUTINO | AA3: INICIO TOP VESPERTINO | AB3: INICIO TOP MATUTINO | AC3: INICIO TOP VESPERTINO | AD3: INICIO TOP MATUTINO | AE3: INICIO TOP VESPERTINO | AF3: INICIO TOP MATUTINO | AG3: INICIO TOP VESPERTINO | AH3: INICIO TOP MATUTINO | AI3: INICIO TOP VESPERTINO | AJ3: INICIO TOP MATUTINO | AK3: INICIO TOP VESPERTINO | AL3: INICIO TOP MATUTINO | AM3: INICIO TOP VESPERTINO | AN3: INICIO TOP MATUTINO | AO3: INICIO TOP VESPERTINO | AP3: INICIO TOP MATUTINO | AQ3: INICIO TOP VESPERTINO | AR3: INICIO TOP MATUTINO | AS3: INICIO TOP VESPERTINO | AT3: INICIO TOP MATUTINO | AU3: INICIO TOP VESPERTINO | AV3: INICIO TOP MATUTINO | AW3: INICIO TOP VESPERTINO | AX3: INICIO TOP MATUTINO | AY3: INICIO TOP VESPERTINO | AZ3: INICIO TOP MATUTINO | BA3: INICIO TOP VESPERTINO | BB3: INICIO TOP MATUTINO | BC3: INICIO TOP VESPERTINO | BD3: INICIO TOP MATUTINO | BE3: INICIO TOP VESPERTINO | BF3: INICIO TOP MATUTINO | BG3: INICIO TOP VESPERTINO | BH3: INICIO TOP MATUTINO | BI3: INICIO TOP VESPERTINO | BJ3: INICIO TOP MATUTINO | BK3: INICIO TOP VESPERTINO | BL3: INICIO TOP MATUTINO | BM3: INICIO TOP VESPERTINO | BN3: KEY
A4: R1 | B4: ALFREDO OLVERA | C4: AZCAPOPARK | D4: 08:49:00 | E4: 16:04:00 | F4: 08:32:00 | H4: 08:36:00 | I4: 16:16:00 | J4: 16:20:00 | L4: 08:38:00 | M4: 15:50:00 | N4: 08:24:00 | R4: 08:47:00 | S4: 16:00:00 | T4: 08:49:00 | U4: 15:59:00 | V4: 15:56:00 | X4: 08:32:00 | Y4: 16:02:00 | Z4: 08:39:00 | AA4: 16:05:00 | AB4: 09:01:00 | AF4: 08:39:00 | AG4: 15:59:00 | AH4: 08:30:00 | AI4: 15:54:00 | AJ4: 08:35:00 | AK4: 15:58:00 | AL4: 08:24:00 | AM4: 16:14:00 | AN4: 08:33:00 | AO4: 15:47:00 | AP4: 08:45:00 | AT4: 08:39:00 | AU4: 03:24:00 | AV4: 08:40:00 | AW4: 03:43:00 | BH4: 0.35833333 | BI4: 0.16388889 | BJ4: 0.35 | BK4: 0.16527778 | BN4: =A4&"|"&B4&"|"&C4 -> R1|ALFREDO OLVERA|AZCAPOPARK
A5: R1 | B5: ALFREDO OLVERA | C5: VALLEJO PARK | F5: 15:42:00 | J5: 08:37:00 | V5: 08:42:00 | BN5: =A5&"|"&B5&"|"&C5 -> R1|ALFREDO OLVERA|VALLEJO PARK
A6: R1 | B6: MARTIN BAUME | C6: GB | D6: 16:01:00 | F6: 08:30:00 | G6: 15:49:00 | H6: 08:31:00 | I6: 16:30:00 | J6: 16:30:00 | L6: 08:55:00 | M6: 15:59:00 | R6: 08:25:00 | S6: 16:21:00 | T6: 16:05:00 | V6: 08:23:00 | W6: 14:13:00 | X6: 16:14:00 | Z6: 08:38:00 | AB6: 08:15:00 | AF6: 08:37:00 | AG6: 16:23:00 | AH6: 08:27:00 | AI6: 16:14:00 | AJ6: 08:19:00 | AK6: 15:54:00 | AL6: 08:26:00 | AM6: 15:54:00 | AN6: 16:56:00 | BH6: 0.35902778 | BI6: 0.15763889 | BJ6: 0.36319444 | BK6: 0.16597222 | BN6: =A6&"|"&B6&"|"&C6 -> R1|MARTIN BAUME|GB
A7: R1 | B7: MARTIN BAUME | C7: CEYLAN | J7: 08:45:00 | X7: 08:43:00 | Z7: 15:30:00 | AN7: 08:28:00 | BN7: =A7&"|"&B7&"|"&C7 -> R1|MARTIN BAUME|CEYLAN
A8: R1 | B8: MARTIN BAUME | C8: 100 METROS | T8: 08:25:00 | BN8: =A8&"|"&B8&"|"&C8 -> R1|MARTIN BAUME|100 METROS
A9: R1 | B9: MARTIN BAUME | C9: PINO | BN9: =A9&"|"&B9&"|"&C9 -> R1|MARTIN BAUME|PINO
A10: R1 | B10: MARTIN BAUME | C10: VALLEJO 1746 | BN10: =A10&"|"&B10&"|"&C10 -> R1|MARTIN BAUME|VALLEJO 1746
A11: R1 | B11: JAIR ABRAHAM GONZALEZ | C11: TLANE PARK III | D11: 09:09:00 | E11: 16:00:00 | F11: 16:02:00 | H11: 08:34:00 | I11: 16:12:00 | J11: 08:40:00 | K11: 16:15:00 | L11: 09:34:00 | M11: 16:16:00 | R11: 08:43:00 | S11: 15:48:00 | T11: 08:32:00 | U11: 16:08:00 | V11: 08:40:00 | W11: 15:53:00 | X11: 08:34:00 | Y11: 15:55:00 | Z11: 08:31:00 | AA11: 15:50:00 | AF11: 08:36:00 | AG11: 15:34:00 | AH11: 08:38:00 | AI11: 15:35:00 | AJ11: 08:24:00 | AK11: 15:56:00 | AL11: 08:35:00 | AM11: 15:51:00 | AN11: 08:51:00 | AO11: 15:39:00 | AT11: 08:39:00 | AU11: 03:33:00 | AV11: 08:35:00 | AW11: 04:21:00 | BH11: 0.35902778 | BI11: 0.15347222 | BJ11: 0.36180556 | BK11: 0.15694444 | BN11: =A11&"|"&B11&"|"&C11 -> R1|JAIR ABRAHAM GONZALEZ|TLANE PARK III
A12: R1 | B12: JAIR ABRAHAM GONZALEZ | C12: VIA MORELOS | F12: 08:38:00 | N12: 08:47:00 | BN12: =A12&"|"&B12&"|"&C12 -> R1|JAIR ABRAHAM GONZALEZ|VIA MORELOS
A13: R1 | B13: JAIR ABRAHAM GONZALEZ | C13: TLANE PARK V | BN13: =A13&"|"&B13&"|"&C13 -> R1|JAIR ABRAHAM GONZALEZ|TLANE PARK V
A14: R1 | B14: JAIR ABRAHAM GONZALEZ | C14: VALLEJO 2000 | BN14: =A14&"|"&B14&"|"&C14 -> R1|JAIR ABRAHAM GONZALEZ|VALLEJO 2000
A15: R1 | B15: JAIR ABRAHAM GONZALEZ | C15: LA PRESA | BN15: =A15&"|"&B15&"|"&C15 -> R1|JAIR ABRAHAM GONZALEZ|LA PRESA
A16: R1 | B16: JAIR ABRAHAM GONZALEZ | C16: CHIQUIHUITE (WALMART) | BN16: =A16&"|"&B16&"|"&C16 -> R1|JAIR ABRAHAM GONZALEZ|CHIQUIHUITE (WALMART)
A17: R1 | B17: GEOVANI PEÑA | C17: LOS REYES | D17: 09:09:00 | E17: 16:11:00 | F17: 08:53:00 | G17: 15:53:00 | H17: 08:04:00 | I17: 16:09:00 | J17: 08:01:00 | K17: 16:32:00 | L17: 08:07:00 | M17: 16:18:00 | N17: 08:39:00 | R17: 08:41:00 | S17: 15:59:00 | T17: 08:05:00 | U17: 15:32:00 | V17: 08:16:00 | W17: 15:59:00 | X17: 09:29:00 | Y17: 16:05:00 | Z17: 07:39:00 | AA17: 16:12:00 | AF17: 08:20:00 | AG17: 16:07:00 | AH17: 08:17:00 | AI17: 16:06:00 | AJ17: 07:56:00 | AK17: 16:27:00 | AL17: 07:52:00 | AM17: 15:59:00 | AN17: 08:04:00 | AO17: 16:07:00 | AP17: 08:34:00 | AT17: 08:14:00 | AU17: 03:52:00 | AV17: 08:28:00 | AW17: 04:10:00 | AX17: 11:33:00 | BB17: 08:29:00 | BC17: 03:58:00 | BN17: =A17&"|"&B17&"|"&C17 -> R1|GEOVANI PEÑA|LOS REYES
A18: R1 | B18: GEOVANI PEÑA | C18: IXTAPALUCA | BN18: =A18&"|"&B18&"|"&C18 -> R1|GEOVANI PEÑA|IXTAPALUCA
A19: R1 | B19: GEOVANI PEÑA | C19: IZTAPALAPA | BN19: =A19&"|"&B19&"|"&C19 -> R1|GEOVANI PEÑA|IZTAPALAPA
A20: R2 | B20: OMAR SANCHEZ | C20: TULTI PARK I | F20: 08:31:00 | G20: 16:29:00 | H20: 08:56:00 | I20: 04:42:00 | J20: 15:48:00 | L20: 16:07:00 | T20: 09:06:00 | U20: 15:41:00 | V20: 08:47:00 | W20: 15:35:00 | X20: 08:59:00 | Y20: 15:41:00 | Z20: 09:03:00 | AA20: 15:54:00 | AF20: 09:01:00 | AG20: 15:24:00 | AH20: 09:03:00 | AI20: 15:47:00 | AJ20: 09:02:00 | AK20: 15:23:00 | AL20: 09:04:00 | AM20: 15:44:00 | AN20: 09:06:00 | AO20: 15:30:00 | AP20: 09:07:00 | AT20: 09:05:00 | AU20: 04:16:00 | AV20: 09:07:00 | AW20: 03:08:00 | BB20: 09:09:00 | BC20: 03:26:00 | BI20: 0.13125 | BJ20: 0.37708333 | BK20: 0.14652778 | BN20: =A20&"|"&B20&"|"&C20 -> R2|OMAR SANCHEZ|TULTI PARK I
A21: R2 | B21: ARTURO ESPINOSA | C21: JAMES WATT | D21: 09:05:00 | E21: 16:01:00 | F21: 08:29:00 | G21: 15:15:00 | H21: 08:23:00 | I21: 15:22:00 | J21: 08:33:00 | K21: 15:18:00 | L21: 08:35:00 | M21: 15:27:00 | T21: 08:31:00 | U21: 15:20:00 | V21: 08:29:00 | W21: 15:44:00 | X21: 08:47:00 | Y21: 15:43:00 | Z21: 08:24:00 | AA21: 15:26:00 | AF21: 08:32:00 | AG21: 15:02:00 | AH21: 08:26:00 | AI21: 15:40:00 | AJ21: 08:43:00 | AK21: 14:56:00 | AL21: 08:04:00 | AM21: 15:13:00 | AN21: 07:58:00 | AO21: 14:53:00 | AT21: 08:12:00 | AU21: 02:51:00 | AV21: 08:23:00 | AW21: 02:20:00 | BB21: 08:56:00 | BC21: 03:18:00 | BD21: 0.41736111 | BH21: 0.35138889 | BI21: 0.125 | BJ21: 0.33958333 | BL21: 0.35625 | BM21: 0.11597222 | BN21: =A21&"|"&B21&"|"&C21 -> R2|ARTURO ESPINOSA|JAMES WATT
A22: R2 | B22: ARTURO VALERIO | C22: LA PALMA | D22: 09:58:00 | E22: 15:40:00 | J22: 08:43:00 | K22: 15:40:00 | L22: 09:01:00 | M22: 17:32:00 | N22: 09:21:00 | R22: 08:43:00 | S22: 17:17:00 | V22: 08:52:00 | W22: 15:28:00 | AF22: 08:48:00 | AG22: 15:53:00 | AL22: 08:57:00 | AM22: 16:02:00 | AP22: 09:04:00 | AV22: 09:20:00 | AW22: 04:08:00 | BB22: 04:47:00 | BN22: =A22&"|"&B22&"|"&C22 -> R2|ARTURO VALERIO|LA PALMA
A23: R2 | B23: ARTURO VALERIO | C23: LA JOYA I Y II | F23: 08:49:00 | G23: 15:58:00 | T23: 08:43:00 | Z23: 08:46:00 | AA23: 16:54:00 | AH23: 09:00:00 | AI23: 15:23:00 | AN23: 08:57:00 | AO23: 15:32:00 | BB23: 11:04:00 | BN23: =A23&"|"&B23&"|"&C23 -> R2|ARTURO VALERIO|LA JOYA I Y II
A24: R2 | B24: ARTURO VALERIO | C24: LA JOYA III | H24: 08:55:00 | I24: 16:14:00 | X24: 08:50:00 | Y24: 16:04:00 | AJ24: 09:01:00 | BN24: =A24&"|"&B24&"|"&C24 -> R2|ARTURO VALERIO|LA JOYA III
A25: R2 | B25: ARTURO VALERIO | C25: LA JOYA IV | BN25: =A25&"|"&B25&"|"&C25 -> R2|ARTURO VALERIO|LA JOYA IV
A26: R2 | B26: ARTURO VALERIO | C26: LA JOYA V | BN26: =A26&"|"&B26&"|"&C26 -> R2|ARTURO VALERIO|LA JOYA V
A27: R2 | B27: ARTURO VALERIO | C27: DIAMANTE | BN27: =A27&"|"&B27&"|"&C27 -> R2|ARTURO VALERIO|DIAMANTE
A28: R2 | B28: ARTURO VALERIO | C28: PUMA | AT28: 09:30:00 | BN28: =A28&"|"&B28&"|"&C28 -> R2|ARTURO VALERIO|PUMA
A29: R2 | B29: MONSERRAT ESQUIVEL | C29: TULTITLAN I | D29: 10:02:00 | E29: 16:11:00 | F29: 08:44:00 | G29: 15:59:00 | H29: 08:56:00 | I29: 16:04:00 | J29: 08:38:00 | L29: 08:59:00 | M29: 15:49:00 | R29: 09:10:00 | S29: 16:13:00 | T29: 10:04:00 | U29: 16:03:00 | V29: 10:02:00 | W29: 15:45:00 | X29: 08:46:00 | Y29: 15:56:00 | Z29: 08:36:00 | AA29: 15:37:00 | AH29: 09:12:00 | AI29: 15:38:00 | AJ29: 15:36:00 | AL29: 08:46:00 | AM29: 15:54:00 | AN29: 09:15:00 | AO29: 15:45:00 | AT29: 09:23:00 | AU29: 03:44:00 | AV29: 09:06:00 | AW29: 04:09:00 | BB29: 03:34:00 | BH29: 0.37916667 | BJ29: 0.42638889 | BK29: 0.15208333 | BN29: =A29&"|"&B29&"|"&C29 -> R2|MONSERRAT ESQUIVEL|TULTITLAN I
A30: R2 | B30: RAFAEL PONCE | C30: TULTITLAN II | D30: 08:50:00 | E30: 16:13:00 | F30: 08:45:00 | G30: 16:00:00 | H30: 08:26:00 | I30: 14:02:00 | J30: 10:00:00 | K30: 15:37:00 | L30: 08:49:00 | M30: 16:12:00 | T30: 08:36:00 | U30: 15:38:00 | V30: 08:52:00 | W30: 15:44:00 | X30: 08:24:00 | Y30: 15:32:00 | Z30: 08:32:00 | AA30: 15:22:00 | AB30: 08:41:00 | AF30: 09:35:00 | AG30: 15:41:00 | AH30: 09:02:00 | AI30: 15:07:00 | AJ30: 08:32:00 | AK30: 15:11:00 | AL30: 08:30:00 | AM30: 15:58:00 | AN30: 08:25:00 | AO30: 16:04:00 | AT30: 09:29:00 | AU30: 03:30:00 | AV30: 08:55:00 | AW30: 03:48:00 | BB30: 09:21:00 | BH30: 0.36041667 | BI30: 0.16736111 | BJ30: 0.37986111 | BK30: 0.18055556 | BN30: =A30&"|"&B30&"|"&C30 -> R2|RAFAEL PONCE|TULTITLAN II
A31: R3 | B31: CARLOS A. CARRILLO | C31: TULTI PARK II | D31: 09:00:00 | F31: 08:41:00 | G31: 15:51:00 | H31: 08:45:00 | I31: 15:50:00 | J31: 08:36:00 | K31: 15:37:00 | L31: 08:26:00 | M31: 15:15:00 | N31: 10:13:00 | R31: 09:42:00 | S31: 17:29:00 | T31: 08:39:00 | U31: 16:08:00 | V31: 08:50:00 | W31: 16:47:00 | X31: 08:40:00 | Y31: 15:19:00 | Z31: 08:43:00 | AA31: 15:50:00 | AB31: 08:54:00 | AF31: 08:42:00 | AG31: 15:05:00 | AH31: 08:39:00 | AI31: 15:21:00 | AJ31: 08:29:00 | AK31: 16:05:00 | AL31: 07:56:00 | AM31: 15:36:00 | AN31: 09:11:00 | AO31: 15:50:00 | AP31: 09:00:00 | AT31: 08:58:00 | AU31: 03:02:00 | AV31: 08:37:00 | AW31: 03:12:00 | AX31: 01:31:00 | AY31: 03:31:00 | BB31: 08:54:00 | BC31: 03:25:00 | BD31: 0.37638889 | BE31: 0.52638889 | BH31: 0.36527778 | BI31: 0.12638889 | BJ31: 0.34861111 | BK31: 0.14444444 | BM31: 0.072222222 | BN31: =A31&"|"&B31&"|"&C31 -> R3|CARLOS A. CARRILLO|TULTI PARK II
A32: R3 | B32: IVAN GONZALEZ | C32: TULTI PARK III | D32: 09:29:00 | E32: 16:47:00 | H32: 08:37:00 | I32: 15:41:00 | J32: 08:53:00 | K32: 15:40:00 | L32: 08:54:00 | M32: 16:08:00 | R32: 08:40:00 | S32: 15:29:00 | T32: 08:34:00 | U32: 15:45:00 | V32: 08:27:00 | W32: 15:32:00 | X32: 08:49:00 | Y32: 15:29:00 | Z32: 08:40:00 | AA32: 15:53:00 | AF32: 08:58:00 | AG32: 15:46:00 | AH32: 08:39:00 | AI32: 15:30:00 | AJ32: 08:51:00 | AK32: 15:29:00 | AL32: 08:46:00 | AM32: 15:37:00 | AN32: 08:41:00 | AO32: 15:23:00 | AT32: 08:28:00 | AU32: 03:12:00 | AV32: 08:50:00 | AW32: 03:25:00 | AX32: 11:38:00 | BB32: 08:41:00 | BC32: 03:26:00 | BN32: =A32&"|"&B32&"|"&C32 -> R3|IVAN GONZALEZ|TULTI PARK III
A33: R3 | B33: ANDREA F. MIRANDA | C33: TULTI PARK IV | D33: 09:05:00 | E33: 15:45:00 | F33: 08:43:00 | G33: 16:04:00 | H33: 08:25:00 | I33: 16:01:00 | J33: 15:43:00 | L33: 08:18:00 | M33: 15:31:00 | N33: 08:25:00 | R33: 08:26:00 | S33: 15:43:00 | T33: 08:40:00 | U33: 15:43:00 | V33: 08:23:00 | W33: 15:12:00 | X33: 08:31:00 | Y33: 15:42:00 | Z33: 08:40:00 | AA33: 16:10:00 | AF33: 08:36:00 | AH33: 08:32:00 | AI33: 15:37:00 | AL33: 15:22:00 | AN33: 08:30:00 | AT33: 08:30:00 | AV33: 05:11:00 | BH33: 0.36458333 | BI33: 0.15208333 | BJ33: 0.38125 | BK33: 0.14861111 | BL33: 0.45347222 | BN33: =A33&"|"&B33&"|"&C33 -> R3|ANDREA F. MIRANDA|TULTI PARK IV
A34: R3 | B34: ANDREA F. MIRANDA | C34: COACALCO | BN34: =A34&"|"&B34&"|"&C34 -> R3|ANDREA F. MIRANDA|COACALCO
A35: R3 | B35: MARCO A. CERVANTES | C35: MEXIQUENSE | D35: 09:15:00 | E35: 16:18:00 | F35: 09:02:00 | G35: 15:48:00 | H35: 08:36:00 | I35: 15:24:00 | J35: 08:41:00 | K35: 15:54:00 | L35: 08:48:00 | M35: 15:10:00 | R35: 08:41:00 | S35: 15:20:00 | T35: 08:31:00 | U35: 15:18:00 | V35: 08:25:00 | W35: 16:14:00 | X35: 08:36:00 | Y35: 15:12:00 | Z35: 08:23:00 | AA35: 15:26:00 | AB35: 08:17:00 | AF35: 08:27:00 | AG35: 15:33:00 | AH35: 08:29:00 | AI35: 15:34:00 | AJ35: 08:32:00 | AK35: 15:32:00 | AL35: 08:24:00 | AM35: 15:07:00 | AN35: 08:26:00 | AO35: 15:07:00 | AP35: 08:21:00 | AT35: 08:43:00 | AU35: 03:16:00 | AV35: 09:25:00 | AW35: 04:10:00 | AX35: 11:00:00 | BB35: 09:09:00 | BC35: 03:56:00 | BD35: 0.42638889 | BH35: 0.36944444 | BJ35: 0.35833333 | BN35: =A35&"|"&B35&"|"&C35 -> R3|MARCO A. CERVANTES|MEXIQUENSE
A36: R3 | B36: PAOLA S. ANSELMO | C36: TULTE PARK | D36: 08:53:00 | E36: 15:25:00 | F36: 08:34:00 | G36: 16:36:00 | H36: 08:09:00 | I36: 16:08:00 | J36: 08:29:00 | K36: 16:11:00 | L36: 08:21:00 | M36: 16:03:00 | R36: 08:33:00 | S36: 15:31:00 | T36: 08:21:00 | U36: 15:55:00 | V36: 08:24:00 | W36: 15:56:00 | X36: 08:40:00 | Y36: 15:19:00 | Z36: 08:33:00 | AA36: 15:22:00 | AF36: 08:48:00 | AG36: 15:13:00 | AH36: 08:40:00 | AI36: 14:51:00 | AJ36: 08:41:00 | AK36: 15:42:00 | AL36: 08:07:00 | AM36: 14:58:00 | AN36: 08:27:00 | AO36: 15:19:00 | AT36: 03:19:00 | AV36: 09:52:00 | BB36: 12:00:00 | BN36: =A36&"|"&B36&"|"&C36 -> R3|PAOLA S. ANSELMO|TULTE PARK
A37: R4 | B37: JESUS BECERRA | C37: LAGO I | BN37: =A37&"|"&B37&"|"&C37 -> R4|JESUS BECERRA|LAGO I
A38: R4 | B38: JESUS BECERRA | C38: LAGO II | D38: 09:02:00 | E38: 15:31:00 | F38: 08:42:00 | G38: 15:24:00 | H38: 08:39:00 | I38: 15:46:00 | J38: 08:23:00 | K38: 15:35:00 | L38: 09:26:00 | M38: 15:37:00 | R38: 08:58:00 | S38: 15:29:00 | T38: 15:37:00 | V38: 08:46:00 | W38: 15:41:00 | X38: 08:49:00 | Y38: 15:10:00 | Z38: 08:25:00 | AA38: 15:52:00 | AB38: 08:48:00 | AF38: 08:05:00 | AG38: 15:28:00 | AH38: 09:10:00 | AI38: 15:25:00 | AJ38: 08:35:00 | AL38: 08:57:00 | AM38: 15:37:00 | AN38: 08:40:00 | AO38: 15:23:00 | AP38: 08:46:00 | AT38: 08:59:00 | AU38: 03:40:00 | AV38: 09:34:00 | AW38: 03:37:00 | BB38: 08:45:00 | BC38: 04:06:00 | BD38: 0.36458333 | BE38: 0.50416667 | BH38: 0.37083333 | BI38: 0.14444444 | BJ38: 0.375 | BK38: 0.15069444 | BN38: =A38&"|"&B38&"|"&C38 -> R4|JESUS BECERRA|LAGO II
A39: R4 | B39: EDGAR S. MARQUEZ | C39: LAGO III | F39: 09:05:00 | G39: 16:01:00 | H39: 08:50:00 | I39: 15:28:00 | J39: 08:49:00 | K39: 15:53:00 | R39: 09:36:00 | S39: 15:22:00 | T39: 08:49:00 | U39: 15:36:00 | X39: 08:32:00 | Y39: 15:41:00 | AF39: 08:26:00 | AG39: 15:30:00 | AH39: 08:31:00 | AI39: 15:30:00 | AL39: 08:28:00 | AM39: 15:42:00 | AN39: 08:32:00 | AO39: 15:35:00 | AT39: 09:29:00 | AU39: 03:13:00 | AV39: 03:44:00 | BJ39: 0.35763889 | BK39: 0.18819444 | BN39: =A39&"|"&B39&"|"&C39 -> R4|EDGAR S. MARQUEZ|LAGO III
A40: R4 | B40: EDGAR S. MARQUEZ | C40: FUNO CENTER | D40: 09:40:00 | E40: 15:53:00 | L40: 08:54:00 | M40: 15:37:00 | V40: 08:43:00 | W40: 15:31:00 | Z40: 08:32:00 | AA40: 15:35:00 | AB40: 08:33:00 | AJ40: 08:34:00 | AK40: 15:21:00 | AN40: 15:44:00 | AT40: 08:38:00 | AV40: 08:43:00 | BB40: 08:24:00 | BC40: 03:29:00 | BH40: 0.36111111 | BI40: 0.15 | BN40: =A40&"|"&B40&"|"&C40 -> R4|EDGAR S. MARQUEZ|FUNO CENTER
...

Sheet DICIEMBRE 2025
B2: 20 DIAS | D2: DICIEMBRE | J2: 2025
B3: REGION | C3: ADMINISTRADOR | D3: UNIDAD DE NEGOCIO | E3: M | F3: % | G3: V | H3: % | I3: TOTAL | J3: CUMPLIMINETO
B4: R1 | C4: ALFREDO OLVERA | D4: AZCAPOPARK | E4: 19 | F4: =E4/20 -> 0.95 | G4: 16 | H4: =G4/20 -> 0.8 | I4: =E4+G4 -> 35 | J4: =I4/40 -> 0.875
B5: R1 | C5: ALFREDO OLVERA | D5: VALLEJO PARK | E5: 3 | F5: =E5/20 -> 0.15 | G5: 0 | H5: =G5/20 -> 0 | I5: =E5+G5 -> 3 | J5: =I5/40 -> 0.075
B6: R1 | C6: MARTIN BAUME | D6: GB | E6: 17 | F6: =E6/20 -> 0.85 | G6: 11 | H6: =G6/20 -> 0.55 | I6: =E6+G6 -> 28 | J6: =I6/40 -> 0.7
B7: R1 | C7: MARTIN BAUME | D7: CEYLAN | E7: 4 | F7: =E7/20 -> 0.2 | G7: 0 | H7: =G7/20 -> 0 | I7: =E7+G7 -> 4 | J7: =I7/40 -> 0.1
B8: R1 | C8: MARTIN BAUME | D8: 100 METROS | E8: 1 | F8: =E8/20 -> 0.05 | G8: 0 | H8: =G8/20 -> 0 | I8: =E8+G8 -> 1 | J8: =I8/40 -> 0.025
B9: R1 | C9: MARTIN BAUME | D9: PINO | E9: 0 | F9: =E9/20 -> 0 | G9: 0 | H9: =G9/20 -> 0 | I9: =E9+G9 -> 0 | J9: =I9/40 -> 0
B10: R1 | C10: MARTIN BAUME | D10: VALLEJO 1746 | E10: 0 | F10: =E10/20 -> 0 | G10: 0 | H10: =G10/20 -> 0 | I10: =E10+G10 -> 0 | J10: =I10/40 -> 0
B11: R1 | C11: JAIR ABRAHAM GONZALEZ | D11: TLANE PARK III | E11: 19 | F11: =E11/20 -> 0.95 | G11: 18 | H11: =G11/20 -> 0.9 | I11: =E11+G11 -> 37 | J11: =I11/40 -> 0.925
B12: R1 | C12: JAIR ABRAHAM GONZALEZ | D12: VIA MORELOS | E12: 1 | F12: =E12/20 -> 0.05 | G12: 0 | H12: =G12/20 -> 0 | I12: =E12+G12 -> 1 | J12: =I12/40 -> 0.025
B13: R1 | C13: JAIR ABRAHAM GONZALEZ | D13: TLANE PARK V | E13: 0 | F13: =E13/20 -> 0 | G13: 0 | H13: =G13/20 -> 0 | I13: =E13+G13 -> 0 | J13: =I13/40 -> 0
B14: R1 | C14: JAIR ABRAHAM GONZALEZ | D14: VALLEJO 2000 | E14: 0 | F14: =E14/20 -> 0 | G14: 0 | H14: =G14/20 -> 0 | I14: =E14+G14 -> 0 | J14: =I14/40 -> 0
B15: R1 | C15: JAIR ABRAHAM GONZALEZ | D15: LA PRESA | E15: 0 | F15: =E15/20 -> 0 | G15: 0 | H15: =G15/20 -> 0 | I15: =E15+G15 -> 0 | J15: =I15/40 -> 0
... B19: R1 | C19: GEOVANI PEÑA | D19: IZTAPALAPA | E19: 0 | F19: =E19/20 -> 0 | G19: 0 | H19: =G19/20 -> 0 | I19: =E19+G19 -> 0 | J19: =I19/40 -> 0
B20: R2 | C20: OMAR SANCHEZ | D20: TULTI PARK I | F20: =E20/20 -> 0 | G20: 16 | H20: =G20/20 -> 0.8 | I20: =E20+G20 -> 16 | J20: =I20/40 -> 0.4
B21: R2 | C21: ARTURO ESPINOSA | D21: JAMES WATT | E21: 19 | F21: =E21/20 -> 0.95 | G21: 19 | H21: =G21/20 -> 0.95 | I21: =E21+G21 -> 38 | J21: =I21/40 -> 0.95
B22: R2 | C22: ARTURO VALERIO | D22: LA PALMA | E22: 9 | F22: =E22/20 -> 0.45 | G22: 8 | H22: =G22/20 -> 0.4 | I22: =E22+G22 -> 17 | J22: =I22/40 -> 0.425
B23: R2 | C23: ARTURO VALERIO | D23: LA JOYA I Y II | E23: 6 | F23: =E23/20 -> 0.3 | G23: 4 | H23: =G23/20 -> 0.2 | I23: =E23+G23 -> 10 | J23: =I23/40 -> 0.25
B24: R2 | C24: ARTURO VALERIO | D24: LA JOYA III | E24: 3 | F24: =E24/20 -> 0.15 | G24: 2 | H24: =G24/20 -> 0.1 | I24: =E24+G24 -> 5 | J24: =I24/40 -> 0.125
B25: R2 | C25: ARTURO VALERIO | D25: LA JOYA IV | E25: 0 | F25: =E25/20 -> 0 | G25: 0 | H25: =G25/20 -> 0 | I25: =E25+G25 -> 0 | J25: =I25/40 -> 0
B26: R2 | C26: ARTURO VALERIO | D26: LA JOYA V | E26: 0 | F26: =E26/20 -> 0 | G26: 0 | H26: =G26/20 -> 0 | I26: =E26+G26 -> 0 | J26: =I26/40 -> 0
B27: R2 | C27: ARTURO VALERIO | D27: DIAMANTE | E27: 0 | F27: =E27/20 -> 0 | G27: 0 | H27: =G27/20 -> 0 | I27: =E27+G27 -> 0 | J27: =I27/40 -> 0
B28: R2 | C28: ARTURO VALERIO | D28: PUMA | E28: 1 | F28: =E28/20 -> 0.05 | G28: 0 | H28: =G28/20 -> 0 | I28: =E28+G28 -> 1 | J28: =I28/40 -> 0.025
B29: R2 | C29: MONSERRAT ESQUIVEL | D29: TULTITLAN I | E29: 19 | F29: =E29/20 -> 0.95 | G29: 15 | H29: =G29/20 -> 0.75 | I29: =E29+G29 -> 34 | J29: =I29/40 -> 0.85
B30: R2 | C30: RAFAEL PONCE | D30: TULTITLAN II | E30: 19 | F30: =E30/20 -> 0.95 | G30: 18 | H30: =G30/20 -> 0.9 | I30: =E30+G30 -> 37 | J30: =I30/40 -> 0.925
B31: R3 | C31: CARLOS A. CARRILLO | D31: TULTI PARK II | E31: 20 | F31: =E31/20 -> 1 | G31: 20 | H31: =G31/20 -> 1 | I31: =E31+G31 -> 40 | J31: =I31/40 -> 1
B32: R3 | C32: IVAN GONZALEZ | D32: TULTI PARK III | E32: 18 | F32: =E32/20 -> 0.9 | G32: 17 | H32: =G32/20 -> 0.85 | I32: =E32+G32 -> 35 | J32: =I32/40 -> 0.875
... B90: R10 | C90: PAOLA N. PERALTA | D90: CANCÚN PARK | E90: 20 | F90: =E90/20 -> 1 | G90: 17 | H90: =G90/20 -> 0.85 | I90: =E90+G90 -> 37 | J90: =I90/40 -> 0.925
B91: GRUPO BALBROS | C91: ADRIANA GARZÓN | D91: MICROPARKS CARTAGENA | E91: 5 | F91: =E91/15 -> 0.33333333 | G91: 6 | H91: =G91/15 -> 0.4 | I91: =E91+G91 -> 11 | J91: =I91/40 -> 0.275
B92: GRUPO BALBROS | C92: ADRIANA GARZÓN | D92: MICROPARKS TULTE I | E92: 5 | F92: =E92/15 -> 0.33333333 | G92: 1 | H92: =G92/15 -> 0.066666667 | I92: =E92+G92 -> 6 | J92: =I92/40 -> 0.15
B93: GRUPO BALBROS | C93: ADRIANA GARZÓN | D93: MICROPARKS TULTE II | E93: 5 | F93: =E93/15 -> 0.33333333 | G93: 5 | H93: =G93/15 -> 0.33333333 | I93: =E93+G93 -> 10 | J93: =I93/40 -> 0.25
B94: GRUPO BALBROS | C94: SEBASTIÁN ROMERO | D94: MICROPARK TULTE III | E94: 15 | F94: =E94/15 -> 1 | G94: 14 | H94: =G94/15 -> 0.93333333 | I94: =E94+G94 -> 29 | J94: =I94/40 -> 0.725
B95: GRUPO BALBROS | C95: ABIGAIL HERNANDEZ | D95: EVOLUTION | E95: 5 | F95: =E95/15 -> 0.33333333 | G95: 7 | H95: =G95/15 -> 0.46666667 | I95: =E95+G95 -> 12 | J95: =I95/40 -> 0.3
B96: GRUPO BALBROS | C96: ABIGAIL HERNANDEZ | D96: LA TEJA | E96: 7 | F96: =E96/15 -> 0.46666667 | G96: 5 | H96: =G96/15 -> 0.33333333 | I96: =E96+G96 -> 12 | J96: =I96/40 -> 0.3
B97: GRUPO BALBROS | C97: CLAUDIA RUIZ | D97: QUERETARO PARK I | E97: 12 | F97: =E97/15 -> 0.8 | G97: 12 | H97: =G97/15 -> 0.8 | I97: =E97+G97 -> 24 | J97: =I97/40 -> 0.6
B98: GRUPO BALBROS | C98: LUIS ALVAREZ | D98: QUERETARO PARK II | E98: 10 | F98: =E98/15 -> 0.66666667 | G98: 6 | H98: =G98/15 -> 0.4 | I98: =E98+G98 -> 16 | J98: =I98/40 -> 0.4

Sheet ENERO 2026
B2: 21 DIAS | D2: ENERO | J2: 2026
B3: REGION | C3: ADMINISTRADOR | D3: UNIDAD DE NEGOCIO | E3: M | F3: % | G3: V | H3: % | I3: TOTAL | J3: CUMPLIMINETO
B4: R1 | C4: ALFREDO OLVERA | D4: AZCAPOPARK | E4: 12 | G4: 13 | J4: =I4/40 -> 0
B5: R1 | C5: ALFREDO OLVERA | D5: VALLEJO PARK | E5: 5 | G5: 6 | J5: =I5/40 -> 0
B6: R1 | C6: MARTIN BAUME | D6: GB | E6: 12 | G6: 13 | J6: =I6/40 -> 0
B7: R1 | C7: MARTIN BAUME | D7: CEYLAN | E7: 6 | G7: 5 | J7: =I7/40 -> 0
B8: R1 | C8: MARTIN BAUME | D8: 100 METROS | E8: 0 | G8: 0 | J8: =I8/40 -> 0
B9: R1 | C9: MARTIN BAUME | D9: PINO | E9: 0 | G9: 0 | J9: =I9/40 -> 0
B10: R1 | C10: MARTIN BAUME | D10: VALLEJO 1746 | E10: 0 | G10: 0 | J10: =I10/40 -> 0
B11: R1 | C11: JAIR ABRAHAM GONZALEZ | D11: TLANE PARK III | E11: 15 | G11: 17 | J11: =I11/40 -> 0
B12: R1 | C12: JAIR ABRAHAM GONZALEZ | D12: VIA MORELOS | E12: 2 | G12: 0 | J12: =I12/40 -> 0
B13: R1 | C13: JAIR ABRAHAM GONZALEZ | D13: TLANE PARK V | E13: 0 | G13: 0 | J13: =I13/40 -> 0
B14: R1 | C14: JAIR ABRAHAM GONZALEZ | D14: VALLEJO 2000 | E14: 0 | G14: 0 | J14: =I14/40 -> 0
B15: R1 | C15: JAIR ABRAHAM GONZALEZ | D15: LA PRESA | E15: 0 | G15: 0 | J15: =I15/40 -> 0
... B24: R2 | C24: ARTURO VALERIO | D24: LA JOYA III | E24: 2 | G24: 3 | J24: =I24/40 -> 0
B25: R2 | C25: ARTURO VALERIO | D25: LA JOYA IV | J25: =I25/40 -> 0
B26: R2 | C26: ARTURO VALERIO | D26: LA JOYA V | J26: =I26/40 -> 0
B27: R2 | C27: ARTURO VALERIO | D27: DIAMANTE | G27: 1 | J27: =I27/40 -> 0
B28: R2 | C28: ARTURO VALERIO | D28: PUMA | E28: 1 | J28: =I28/40 -> 0
B29: R2 | C29: MONSERRAT ESQUIVEL | D29: TULTITLAN I | E29: 18 | G29: 17 | J29: =I29/40 -> 0
B30: R2 | C30: RAFAEL PONCE | D30: TULTITLAN II | E30: 16 | G30: 14 | J30: =I30/40 -> 0
B31: R3 | C31: CARLOS A. CARRILLO | D31: TULTI PARK II | E31: 18 | G31: 18 | J31: =I31/40 -> 0
B32: R3 | C32: IVAN GONZALEZ | D32: TULTI PARK III | E32: 18 | G32: 18 | J32: =I32/40 -> 0
B33: R3 | C33: ANDREA F. MIRANDA | D33: TULTI PARK IV | E33: 18 | G33: 18 | J33: =I33/40 -> 0
B34: R3 | C34: ANDREA F. MIRANDA | D34: COACALCO | E34: 1 | G34: 0 | J34: =I34/40 -> 0
B35: R3 | C35: MARCO A. CERVANTES | D35: MEXIQUENSE | E35: 18 | G35: 18 | J35: =I35/40 -> 0
B36: R3 | C36: MARCO A. CERVANTES | D36: COACALCO II | E36: 3 | G36: 1
B37: R3 | C37: PAOLA S. ANSELMO | D37: TULTE PARK | E37: 18 | G37: 18 | J37: =I37/40 -> 0
B38: R4 | C38: JESUS BECERRA | D38: LAGO I | E38: 0 | G38: 0 | J38: =I38/40 -> 0
B39: R4 | C39: JESUS BECERRA | D39: LAGO II | E39: 18 | G39: 17 | J39: =I39/40 -> 0
B40: R4 | C40: EDGAR S. MARQUEZ | D40: LAGO III | E40: 6 | G40: 5 | J40: =I40/40 -> 0
B41: R4 | C41: EDGAR S. MARQUEZ | D41: FUNO CENTER | E41: 10 | G41: 10 | J41: =I41/40 -> 0
B42: R4 | C42: ANTONIO MARTINEZ | D42: SMO I | E42: 17 | G42: 18 | J42: =I42/40 -> 0
B43: R4 | C43: ANTONIO MARTINEZ | D43: SMO II | E43: 16 | G43: 14 | J43: =I43/40 -> 0
B44: R4 | C44: GERARDO ALONSO | D44: SMO III | E44: 16 | G44: 14 | J44: =I44/40 -> 0
B45: R4 | C45: JULIO CESAR NERI | D45: TLANE PARK IV/ BARRIENTOS II | E45: 18 | G45: 18 | J45: =I45/40 -> 0
B46: R4 | C46: JOSUE GUADARRAMA | D46: ATIZAPAN PARK | E46: 18 | G46: 18 | J46: =I46/40 -> 0
B47: R5 | C47: JUAN C. HERNANDEZ | D47: TEPOZOTLAN PARK | E47: 16 | G47: 17 | J47: =I47/40 -> 0
B48: R5 | C48: JUAN C. HERNANDEZ | D48: TEPOZOTLAN (CONVENTO). | E48: 0 | G48: 0 | J48: =I48/40 -> 0
... B63: R6 | C63: ANA BRITO | D63: QUERETARO PARK III | E63: 12 | G63: 9 | J63: =I63/40 -> 0
...

Sheet TOP FEBRERO 2026
A1: Región | B1: Administrador | C1: Unidad de Negocio | D1: 46054 | F1: 46055 | H1: 46056 | J1: 46057 | L1: 46058 | N1: 46059 | P1: 46060 | R1: 46061 | T1: 46062 | V1: 46063 | X1: 46064 | Z1: 46065 | AB1: 46066 | AD1: 46067 | AF1: 46068 | AH1: 46069 | AJ1: 46070 | AL1: 46071 | AN1: 46072 | AP1: 46073 | AR1: 46074 | AT1: 46075 | AV1: 46076 | AX1: 46077 | AZ1: 46078 | BB1: 46079 | BD1: 46080 | BF1: 46081 | BH1: MATUTINO | BI1: VESPERTINO | BJ1: SÁBADOS
D2: Mat | E2: Vesp | F2: Mat | G2: Vesp | H2: Mat | I2: Vesp | J2: Mat | K2: Vesp | L2: Mat | M2: Vesp | N2: Mat | O2: Vesp | P2: Mat | Q2: Vesp | R2: Mat | S2: Vesp | T2: Mat | U2: Vesp | V2: Mat | W2: Vesp | X2: Mat | Y2: Vesp | Z2: Mat | AA2: Vesp | AB2: Mat | AC2: Vesp | AD2: Mat | AE2: Vesp | AF2: Mat | AG2: Vesp | AH2: Mat | AI2: Vesp | AJ2: Mat | AK2: Vesp | AL2: Mat | AM2: Vesp | AN2: Mat | AO2: Vesp | AP2: Mat | AQ2: Vesp | AR2: Mat | AS2: Vesp | AT2: Mat | AU2: Vesp | AV2: Mat | AW2: Vesp | AX2: Mat | AY2: Vesp | AZ2: Mat | BA2: Vesp | BB2: Mat | BC2: Vesp | BD2: Mat | BE2: Vesp | BF2: Mat | BG2: Vesp | BH2: Total Matutinos (L-V) | BI2: Total Vespertinos (L-V) | BJ2: Sábados
A3: R1 | B3: ALFREDO OLVERA | C3: AZCAPOPARK | H3: 0.35694444 | J3: 0.35694444 | K3: 0.23958333 | L3: 0.35486111 | M3: 0.16736111 | N3: 0.35763889 | O3: 0.16736111 | P3: 0.35486111 | T3: 0.35486111 | U3: 0.16597222 | V3: 0.35694444 | W3: 0.16666667 | X3: 0.35763889 | Y3: 0.16805556 | AA3: 0.17361111 | AC3: 0.15069444 | AH3: 0.35694444 | AI3: 0.16666667 | AJ3: 0.35555556 | AK3: 0.19305556 | AL3: 0.35625 | AM3: 0.18125 | AN3: 0.35625 | AO3: 0.16041667 | AP3: 0.35486111 | AQ3: 0.16527778 | AV3: 0.35555556 | AW3: 0.18680556 | AX3: 0.35277778 | AZ3: 0.35694444 | BA3: 0.18472222 | BB3: 0.35555556 | BC3: 0.18263889 | BD3: 0.35902778 | BE3: 0.17916667 | BH3: =SUM(IF(AND(D3<>"",WEEKDAY(D$1,2)<6),1,0),IF(AND(F3<>"",WEEKDAY(F$1,2)<6),1,0),IF(AND(H3<>"",WEEKDAY(H$1,2)<6),1,0),IF(AND(J3<>"",WEEKDAY(J$1,2)<6),1,0),IF(AND(L3<>"",WEEKDAY(L$1,2)<6),1,0),IF(AND(N3<>"",WEEKDAY(N$1,2)<6),1,0),IF(AND(P3<>"",WEEKDAY(P$1,2)<6),1,0),IF(AND(R3<>"",WEEKDAY(R$1,2)<6),1,0),IF(AND(T3<>"",WEEKDAY(T$1,2)<6),1,0),IF(AND(V3<>"",WEEKDAY(V$1,2)<6),1,0),IF(AND(X3<>"",WEEKDAY(X$1,2)<6),1,0),IF(AND(Z3<>"",WEEKDAY(Z$1,2)<6),1,0),IF(AND(AB3<>"",WEEKDAY(AB$1,2)<6),1,0),IF(AND(AD3<>"",WEEKDAY(AD$1,2)<6),1,0),IF(AND(AF3<>"",WEEKDAY(AF$1,2)<6),1,0),IF(AND(AH3<>"",WEEKDAY(AH$1,2)<6),1,0),IF(AND(AJ3<>"",WEEKDAY(AJ$1,2)<6),1,0),IF(AND(AL3<>"",WEEKDAY(AL$1,2)<6),1,0),IF(AND(AN3<>"",WEEKDAY(AN$1,2)<6),1,0),IF(AND(AP3<>"",WEEKDAY(AP$1,2)<6),1,0),IF(AND(AR3<>"",WEEKDAY(AR$1,2)<6),1,0),IF(AND(AT3<>"",WEEKDAY(AT$1,2)<6),1,0),IF(AND(AV3<>"",WEEKDAY(AV$1,2)<6),1,0),IF(AND(AX3<>"",WEEKDAY(AX$1,2)<6),1,0),IF(AND(AZ3<>"",WEEKDAY(AZ$1,2)<6),1,0),IF(AND(BB3<>"",WEEKDAY(BB$1,2)<6),1,0),IF(AND(BD3<>"",WEEKDAY(BD$1,2)<6),1,0),IF(AND(BF3<>"",WEEKDAY(BF$1,2)<6),1,0)) -> 17 | BI3: =SUM(IF(AND(E3<>"",WEEKDAY(D$1,2)<6),1,0),IF(AND(G3<>"",WEEKDAY(F$1,2)<6),1,0),IF(AND(I3<>"",WEEKDAY(H$1,2)<6),1,0),IF(AND(K3<>"",WEEKDAY(J$1,2)<6),1,0),IF(AND(M3<>"",WEEKDAY(L$1,2)<6),1,0),IF(AND(O3<>"",WEEKDAY(N$1,2)<6),1,0),IF(AND(Q3<>"",WEEKDAY(P$1,2)<6),1,0),IF(AND(S3<>"",WEEKDAY(R$1,2)<6),1,0),IF(AND(U3<>"",WEEKDAY(T$1,2)<6),1,0),IF(AND(W3<>"",WEEKDAY(V$1,2)<6),1,0),IF(AND(Y3<>"",WEEKDAY(X$1,2)<6),1,0),IF(AND(AA3<>"",WEEKDAY(Z$1,2)<6),1,0),IF(AND(AC3<>"",WEEKDAY(AB$1,2)<6),1,0),IF(AND(AE3<>"",WEEKDAY(AD$1,2)<6),1,0),IF(AND(AG3<>"",WEEKDAY(AF$1,2)<6),1,0),IF(AND(AI3<>"",WEEKDAY(AH$1,2)<6),1,0),IF(AND(AK3<>"",WEEKDAY(AJ$1,2)<6),1,0),IF(AND(AM3<>"",WEEKDAY(AL$1,2)<6),1,0),IF(AND(AO3<>"",WEEKDAY(AN$1,2)<6),1,0),IF(AND(AQ3<>"",WEEKDAY(AP$1,2)<6),1,0),IF(AND(AS3<>"",WEEKDAY(AR$1,2)<6),1,0),IF(AND(AU3<>"",WEEKDAY(AT$1,2)<6),1,0),IF(AND(AW3<>"",WEEKDAY(AV$1,2)<6),1,0),IF(AND(AY3<>"",WEEKDAY(AX$1,2)<6),1,0),IF(AND(BA3<>"",WEEKDAY(AZ$1,2)<6),1,0),IF(AND(BC3<>"",WEEKDAY(BB$1,2)<6),1,0),IF(AND(BE3<>"",WEEKDAY(BD$1,2)<6),1,0),IF(AND(BG3<>"",WEEKDAY(BF$1,2)<6),1,0)) -> 17 | BJ3: =SUM(IF(AND((D3<>"" )+(E3<>""),WEEKDAY(D$1,2)=6),1,0),IF(AND((F3<>"" )+(G3<>""),WEEKDAY(F$1,2)=6),1,0),IF(AND((H3<>"" )+(I3<>""),WEEKDAY(H$1,2)=6),1,0),IF(AND((J3<>"" )+(K3<>""),WEEKDAY(J$1,2)=6),1,0),IF(AND((L3<>"" )+(M3<>""),WEEKDAY(L$1,2)=6),1,0),IF(AND((N3<>"" )+(O3<>""),WEEKDAY(N$1,2)=6),1,0),IF(AND((P3<>"" )+(Q3<>""),WEEKDAY(P$1,2)=6),1,0),IF(AND((R3<>"" )+(S3<>""),WEEKDAY(R$1,2)=6),1,0),IF(AND((T3<>"" )+(U3<>""),WEEKDAY(T$1,2)=6),1,0),IF(AND((V3<>"" )+(W3<>""),WEEKDAY(V$1,2)=6),1,0),IF(AND((X3<>"" )+(Y3<>""),WEEKDAY(X$1,2)=6),1,0),IF(AND((Z3<>"" )+(AA3<>""),WEEKDAY(Z$1,2)=6),1,0),IF(AND((AB3<>"" )+(AC3<>""),WEEKDAY(AB$1,2)=6),1,0),IF(AND((AD3<>"" )+(AE3<>""),WEEKDAY(AD$1,2)=6),1,0),IF(AND((AF3<>"" )+(AG3<>""),WEEKDAY(AF$1,2)=6),1,0),IF(AND((AH3<>"" )+(AI3<>""),WEEKDAY(AH$1,2)=6),1,0),IF(AND((AJ3<>"" )+(AK3<>""),WEEKDAY(AJ$1,2)=6),1,0),IF(AND((AL3<>"" )+(AM3<>""),WEEKDAY(AL$1,2)=6),1,0),IF(AND((AN3<>"" )+(AO3<>""),WEEKDAY(AN$1,2)=6),1,0),IF(AND((AP3<>"" )+(AQ3<>""),WEEKDAY(AP$1,2)=6),1,0),IF(AND((AR3<>"" )+(AS3<>""),WEEKDAY(AR$1,2)=6),1,0),IF(AND((AT3<>"" )+(AU3<>""),WEEKDAY(AT$1,2)=6),1,0),IF(AND((AV3<>"" )+(AW3<>""),WEEKDAY(AV$1,2)=6),1,0),IF(AND((AX3<>"" )+(AY3<>""),WEEKDAY(AX$1,2)=6),1,0),IF(AND((AZ3<>"" )+(BA3<>""),WEEKDAY(AZ$1,2)=6),1,0),IF(AND((BB3<>"" )+(BC3<>""),WEEKDAY(BB$1,2)=6),1,0),IF(AND((BD3<>"" )+(BE3<>""),WEEKDAY(BD$1,2)=6),1,0),IF(AND((BF3<>"" )+(BG3<>""),WEEKDAY(BF$1,2)=6),1,0)) -> 1
A4: R1 | B4: ALFREDO OLVERA | C4: VALLEJO PARK | Z4: 0.35625 | AB4: 0.35277778 | AR4: 0.35902778 | AS4: 0.53958333 | BH4: =SUM(IF(AND(D4<>"",WEEKDAY(D$1,2)<6),1,0),IF(AND(F4<>"",WEEKDAY(F$1,2)<6),1,0),IF(AND(H4<>"",WEEKDAY(H$1,2)<6),1,0),IF(AND(J4<>"",WEEKDAY(J$1,2)<6),1,0),IF(AND(L4<>"",WEEKDAY(L$1,2)<6),1,0),IF(AND(N4<>"",WEEKDAY(N$1,2)<6),1,0),IF(AND(P4<>"",WEEKDAY(P$1,2)<6),1,0),IF(AND(R4<>"",WEEKDAY(R$1,2)<6),1,0),IF(AND(T4<>"",WEEKDAY(T$1,2)<6),1,0),IF(AND(V4<>"",WEEKDAY(V$1,2)<6),1,0),IF(AND(X4<>"",WEEKDAY(X$1,2)<6),1,0),IF(AND(Z4<>"",WEEKDAY(Z$1,2)<6),1,0),IF(AND(AB4<>"",WEEKDAY(AB$1,2)<6),1,0),IF(AND(AD4<>"",WEEKDAY(AD$1,2)<6),1,0),IF(AND(AF4<>"",WEEKDAY(AF$1,2)<6),1,0),IF(AND(AH4<>"",WEEKDAY(AH$1,2)<6),1,0),IF(AND(AJ4<>"",WEEKDAY(AJ$1,2)<6),1,0),IF(AND(AL4<>"",WEEKDAY(AL$1,2)<6),1,0),IF(AND(AN4<>"",WEEKDAY(AN$1,2)<6),1,0),IF(AND(AP4<>"",WEEKDAY(AP$1,2)<6),1,0),IF(AND(AR4<>"",WEEKDAY(AR$1,2)<6),1,0),IF(AND(AT4<>"",WEEKDAY(AT$1,2)<6),1,0),IF(AND(AV4<>"",WEEKDAY(AV$1,2)<6),1,0),IF(AND(AX4<>"",WEEKDAY(AX$1,2)<6),1,0),IF(AND(AZ4<>"",WEEKDAY(AZ$1,2)<6),1,0),IF(AND(BB4<>"",WEEKDAY(BB$1,2)<6),1,0),IF(AND(BD4<>"",WEEKDAY(BD$1,2)<6),1,0),IF(AND(BF4<>"",WEEKDAY(BF$1,2)<6),1,0)) -> 2 | BI4: =SUM(IF(AND(E4<>"",WEEKDAY(D$1,2)<6),1,0),IF(AND(G4<>"",WEEKDAY(F$1,2)<6),1,0),IF(AND(I4<>"",WEEKDAY(H$1,2)<6),1,0),IF(AND(K4<>"",WEEKDAY(J$1,2)<6),1,0),IF(AND(M4<>"",WEEKDAY(L$1,2)<6),1,0),IF(AND(O4<>"",WEEKDAY(N$1,2)<6),1,0),IF(AND(Q4<>"",WEEKDAY(P$1,2)<6),1,0),IF(AND(S4<>"",WEEKDAY(R$1,2)<6),1,0),IF(AND(U4<>"",WEEKDAY(T$1,2)<6),1,0),IF(AND(W4<>"",WEEKDAY(V$1,2)<6),1,0),IF(AND(Y4<>"",WEEKDAY(X$1,2)<6),1,0),IF(AND(AA4<>"",WEEKDAY(Z$1,2)<6),1,0),IF(AND(AC4<>"",WEEKDAY(AB$1,2)<6),1,0),IF(AND(AE4<>"",WEEKDAY(AD$1,2)<6),1,0),IF(AND(AG4<>"",WEEKDAY(AF$1,2)<6),1,0),IF(AND(AI4<>"",WEEKDAY(AH$1,2)<6),1,0),IF(AND(AK4<>"",WEEKDAY(AJ$1,2)<6),1,0),IF(AND(AM4<>"",WEEKDAY(AL$1,2)<6),1,0),IF(AND(AO4<>"",WEEKDAY(AN$1,2)<6),1,0),IF(AND(AQ4<>"",WEEKDAY(AP$1,2)<6),1,0),IF(AND(AS4<>"",WEEKDAY(AR$1,2)<6),1,0),IF(AND(AU4<>"",WEEKDAY(AT$1,2)<6),1,0),IF(AND(AW4<>"",WEEKDAY(AV$1,2)<6),1,0),IF(AND(AY4<>"",WEEKDAY(AX$1,2)<6),1,0),IF(AND(BA4<>"",WEEKDAY(AZ$1,2)<6),1,0),IF(AND(BC4<>"",WEEKDAY(BB$1,2)<6),1,0),IF(AND(BE4<>"",WEEKDAY(BD$1,2)<6),1,0),IF(AND(BG4<>"",WEEKDAY(BF$1,2)<6),1,0)) -> 0 | BJ4: =SUM(IF(AND((D4<>"" )+(E4<>""),WEEKDAY(D$1,2)=6),1,0),IF(AND((F4<>"" )+(G4<>""),WEEKDAY(F$1,2)=6),1,0),IF(AND((H4<>"" )+(I4<>""),WEEKDAY(H$1,2)=6),1,0),IF(AND((J4<>"" )+(K4<>""),WEEKDAY(J$1,2)=6),1,0),IF(AND((L4<>"" )+(M4<>""),WEEKDAY(L$1,2)=6),1,0),IF(AND((N4<>"" )+(O4<>""),WEEKDAY(N$1,2)=6),1,0),IF(AND((P4<>"" )+(Q4<>""),WEEKDAY(P$1,2)=6),1,0),IF(AND((R4<>"" )+(S4<>""),WEEKDAY(R$1,2)=6),1,0),IF(AND((T4<>"" )+(U4<>""),WEEKDAY(T$1,2)=6),1,0),IF(AND((V4<>"" )+(W4<>""),WEEKDAY(V$1,2)=6),1,0),IF(AND((X4<>"" )+(Y4<>""),WEEKDAY(X$1,2)=6),1,0),IF(AND((Z4<>"" )+(AA4<>""),WEEKDAY(Z$1,2)=6),1,0),IF(AND((AB4<>"" )+(AC4<>""),WEEKDAY(AB$1,2)=6),1,0),IF(AND((AD4<>"" )+(AE4<>""),WEEKDAY(AD$1,2)=6),1,0),IF(AND((AF4<>"" )+(AG4<>""),WEEKDAY(AF$1,2)=6),1,0),IF(AND((AH4<>"" )+(AI4<>""),WEEKDAY(AH$1,2)=6),1,0),IF(AND((AJ4<>"" )+(AK4<>""),WEEKDAY(AJ$1,2)=6),1,0),IF(AND((AL4<>"" )+(AM4<>""),WEEKDAY(AL$1,2)=6),1,0),IF(AND((AN4<>"" )+(AO4<>""),WEEKDAY(AN$1,2)=6),1,0),IF(AND((AP4<>"" )+(AQ4<>""),WEEKDAY(AP$1,2)=6),1,0),IF(AND((AR4<>"" )+(AS4<>""),WEEKDAY(AR$1,2)=6),1,0),IF(AND((AT4<>"" )+(AU4<>""),WEEKDAY(AT$1,2)=6),1,0),IF(AND((AV4<>"" )+(AW4<>""),WEEKDAY(AV$1,2)=6),1,0),IF(AND((AX4<>"" )+(AY4<>""),WEEKDAY(AX$1,2)=6),1,0),IF(AND((AZ4<>"" )+(BA4<>""),WEEKDAY(AZ$1,2)=6),1,0),IF(AND((BB4<>"" )+(BC4<>""),WEEKDAY(BB$1,2)=6),1,0),IF(AND((BD4<>"" )+(BE4<>""),WEEKDAY(BD$1,2)=6),1,0),IF(AND((BF4<>"" )+(BG4<>""),WEEKDAY(BF$1,2)=6),1,0)) -> 1
A5: R1 | B5: MARTIN BAUME | C5: GB | H5: 0.35555556 | J5: 0.35347222 | K5: 0.16666667 | L5: 0.35833333 | M5: 0.18611111 | N5: 0.36458333 | O5: 0.17777778 | P5: 0.34930556 | T5: 0.35486111 | U5: 0.15763889 | V5: 0.35277778 | W5: 0.14375 | Y5: 0.2 | Z5: 0.36111111 | AA5: 0.16597222 | AB5: 0.35555556 | AC5: 0.16180556 | AH5: 0.35347222 | AI5: 0.19027778 | AJ5: 0.34861111 | AK5: 0.16041667 | AL5: 0.36180556 | AM5: 0.13611111 | AN5: 0.34791667 | AO5: 0.175 | AP5: 0.34930556 | AQ5: 0.19583333 | AR5: 0.34513889 | AV5: 0.33611111 | AW5: 0.14791667 | AX5: 0.35625 | BA5: 0.15277778 | BD5: 0.38333333 | BE5: 0.19722222 | BH5: =SUM(IF(AND(D5<>"",WEEKDAY(D$1,2)<6),1,0),IF(AND(F5<>"",WEEKDAY(F$1,2)<6),1,0),IF(AND(H5<>"",WEEKDAY(H$1,2)<6),1,0),IF(AND(J5<>"",WEEKDAY(J$1,2)<6),1,0),IF(AND(L5<>"",WEEKDAY(L$1,2)<6),1,0),IF(AND(N5<>"",WEEKDAY(N$1,2)<6),1,0),IF(AND(P5<>"",WEEKDAY(P$1,2)<6),1,0),IF(AND(R5<>"",WEEKDAY(R$1,2)<6),1,0),IF(AND(T5<>"",WEEKDAY(T$1,2)<6),1,0),IF(AND(V5<>"",WEEKDAY(V$1,2)<6),1,0),IF(AND(X5<>"",WEEKDAY(X$1,2)<6),1,0),IF(AND(Z5<>"",WEEKDAY(Z$1,2)<6),1,0),IF(AND(AB5<>"",WEEKDAY(AB$1,2)<6),1,0),IF(AND(AD5<>"",WEEKDAY(AD$1,2)<6),1,0),IF(AND(AF5<>"",WEEKDAY(AF$1,2)<6),1,0),IF(AND(AH5<>"",WEEKDAY(AH$1,2)<6),1,0),IF(AND(AJ5<>"",WEEKDAY(AJ$1,2)<6),1,0),IF(AND(AL5<>"",WEEKDAY(AL$1,2)<6),1,0),IF(AND(AN5<>"",WEEKDAY(AN$1,2)<6),1,0),IF(AND(AP5<>"",WEEKDAY(AP$1,2)<6),1,0),IF(AND(AR5<>"",WEEKDAY(AR$1,2)<6),1,0),IF(AND(AT5<>"",WEEKDAY(AT$1,2)<6),1,0),IF(AND(AV5<>"",WEEKDAY(AV$1,2)<6),1,0),IF(AND(AX5<>"",WEEKDAY(AX$1,2)<6),1,0),IF(AND(AZ5<>"",WEEKDAY(AZ$1,2)<6),1,0),IF(AND(BB5<>"",WEEKDAY(BB$1,2)<6),1,0),IF(AND(BD5<>"",WEEKDAY(BD$1,2)<6),1,0),IF(AND(BF5<>"",WEEKDAY(BF$1,2)<6),1,0)) -> 16 | BI5: =SUM(IF(AND(E5<>"",WEEKDAY(D$1,2)<6),1,0),IF(AND(G5<>"",WEEKDAY(F$1,2)<6),1,0),IF(AND(I5<>"",WEEKDAY(H$1,2)<6),1,0),IF(AND(K5<>"",WEEKDAY(J$1,2)<6),1,0),IF(AND(M5<>"",WEEKDAY(L$1,2)<6),1,0),IF(AND(O5<>"",WEEKDAY(N$1,2)<6),1,0),IF(AND(Q5<>"",WEEKDAY(P$1,2)<6),1,0),IF(AND(S5<>"",WEEKDAY(R$1,2)<6),1,0),IF(AND(U5<>"",WEEKDAY(T$1,2)<6),1,0),IF(AND(W5<>"",WEEKDAY(V$1,2)<6),1,0),IF(AND(Y5<>"",WEEKDAY(X$1,2)<6),1,0),IF(AND(AA5<>"",WEEKDAY(Z$1,2)<6),1,0),IF(AND(AC5<>"",WEEKDAY(AB$1,2)<6),1,0),IF(AND(AE5<>"",WEEKDAY(AD$1,2)<6),1,0),IF(AND(AG5<>"",WEEKDAY(AF$1,2)<6),1,0),IF(AND(AI5<>"",WEEKDAY(AH$1,2)<6),1,0),IF(AND(AK5<>"",WEEKDAY(AJ$1,2)<6),1,0),IF(AND(AM5<>"",WEEKDAY(AL$1,2)<6),1,0),IF(AND(AO5<>"",WEEKDAY(AN$1,2)<6),1,0),IF(AND(AQ5<>"",WEEKDAY(AP$1,2)<6),1,0),IF(AND(AS5<>"",WEEKDAY(AR$1,2)<6),1,0),IF(AND(AU5<>"",WEEKDAY(AT$1,2)<6),1,0),IF(AND(AW5<>"",WEEKDAY(AV$1,2)<6),1,0),IF(AND(AY5<>"",WEEKDAY(AX$1,2)<6),1,0),IF(AND(BA5<>"",WEEKDAY(AZ$1,2)<6),1,0),IF(AND(BC5<>"",WEEKDAY(BB$1,2)<6),1,0),IF(AND(BE5<>"",WEEKDAY(BD$1,2)<6),1,0),IF(AND(BG5<>"",WEEKDAY(BF$1,2)<6),1,0)) -> 16 | BJ5: =SUM(IF(AND((D5<>"" )+(E5<>""),WEEKDAY(D$1,2)=6),1,0),IF(AND((F5<>"" )+(G5<>""),WEEKDAY(F$1,2)=6),1,0),IF(AND((H5<>"" )+(I5<>""),WEEKDAY(H$1,2)=6),1,0),IF(AND((J5<>"" )+(K5<>""),WEEKDAY(J$1,2)=6),1,0),IF(AND((L5<>"" )+(M5<>""),WEEKDAY(L$1,2)=6),1,0),IF(AND((N5<>"" )+(O5<>""),WEEKDAY(N$1,2)=6),1,0),IF(AND((P5<>"" )+(Q5<>""),WEEKDAY(P$1,2)=6),1,0),IF(AND((R5<>"" )+(S5<>""),WEEKDAY(R$1,2)=6),1,0),IF(AND((T5<>"" )+(U5<>""),WEEKDAY(T$1,2)=6),1,0),IF(AND((V5<>"" )+(W5<>""),WEEKDAY(V$1,2)=6),1,0),IF(AND((X5<>"" )+(Y5<>""),WEEKDAY(X$1,2)=6),1,0),IF(AND((Z5<>"" )+(AA5<>""),WEEKDAY(Z$1,2)=6),1,0),IF(AND((AB5<>"" )+(AC5<>""),WEEKDAY(AB$1,2)=6),1,0),IF(AND((AD5<>"" )+(AE5<>""),WEEKDAY(AD$1,2)=6),1,0),IF(AND((AF5<>"" )+(AG5<>""),WEEKDAY(AF$1,2)=6),1,0),IF(AND((AH5<>"" )+(AI5<>""),WEEKDAY(AH$1,2)=6),1,0),IF(AND((AJ5<>"" )+(AK5<>""),WEEKDAY(AJ$1,2)=6),1,0),IF(AND((AL5<>"" )+(AM5<>""),WEEKDAY(AL$1,2)=6),1,0),IF(AND((AN5<>"" )+(AO5<>""),WEEKDAY(AN$1,2)=6),1,0),IF(AND((AP5<>"" )+(AQ5<>""),WEEKDAY(AP$1,2)=6),1,0),IF(AND((AR5<>"" )+(AS5<>""),WEEKDAY(AR$1,2)=6),1,0),IF(AND((AT5<>"" )+(AU5<>""),WEEKDAY(AT$1,2)=6),1,0),IF(AND((AV5<>"" )+(AW5<>""),WEEKDAY(AV$1,2)=6),1,0),IF(AND((AX5<>"" )+(AY5<>""),WEEKDAY(AX$1,2)=6),1,0),IF(AND((AZ5<>"" )+(BA5<>""),WEEKDAY(AZ$1,2)=6),1,0),IF(AND((BB5<>"" )+(BC5<>""),WEEKDAY(BB$1,2)=6),1,0),IF(AND((BD5<>"" )+(BE5<>""),WEEKDAY(BD$1,2)=6),1,0),IF(AND((BF5<>"" )+(BG5<>""),WEEKDAY(BF$1,2)=6),1,0)) -> 2
